Workbook

Sheet 판정
B2: =TRIM(IF(AND(C15="피부양자",C39="확인 필요"),"피부양자 판정이 갈려요: 1천만원 이하 금융소득을 소득에 넣는지 공단 안내에 없어요(기준값 시트). ","")&IF(AND(N(C14)>0,C31>0),"해외주식 배당이 있다면 외국에서 낸 세금 공제를 넣지 않아 더 내는 소득세가 실제보다 크게 나올 수 있어요. ",""))
B3: =IF(C15="피부양자",IF(C39="유지","피부양자 유지 · 건보료",IF(C39="탈락","피부양자에서 빠지면 지역가입자로 내는 건보료","피부양자 판정 확인 필요")),"금융소득 때문에 붙는 건보료")
B4: =IF(C15="피부양자",IF(C39="유지","월 0원",IF(C39="탈락","월 "&TEXT(C49,"#,##0")&"원","유지 또는 월 "&TEXT(C49,"#,##0")&"원")),"월 "&TEXT(C51,"#,##0")&"원")
B7: =IF(C15="피부양자",IF(C39="유지","지금 금액이면 건보료가 붙지 않아요",IF(C39="탈락","탈락하면 지역가입자 월 "&TEXT(C49,"#,##0")&"원"&" · 금융소득이 없어도 월 "&TEXT(C50,"#,##0")&"원","공단(1577-1000) 확인 필요 · 탈락하면 지역가입자 월 "&TEXT(C49,"#,##0")&"원")),IF(C51<=0,"금융소득 때문에 늘어나는 건보료는 없어요 · 전체 월 "&TEXT(C49,"#,##0")&"원","지금 이 금액이면 건보료가 월 "&TEXT(C51,"#,##0")&"원"&" 붙어요 · 전체 월 "&TEXT(C49,"#,##0")&"원"))
B8: =IF(C31<=0,"종합과세로 더 내는 소득세는 없어요","종합과세로 소득세를 1년에 "&TEXT(C31,"#,##0")&"원"&" 더 내요")
B9: 종합과세로 더 내는 소득세(연) | C9: 피부양자 판정 | E9: 지역가입자면 월 건보료
B10: =C31 | C10: =C39 | E10: =C49
B11: 넣는 칸 | E11: 1년 금액, 세금 떼기 전 · 빈칸은 0
B12: 이자 | C12: 8000000 | D12: 원 | E12: 예금·적금·채권 이자
B13: 배당 · 국내 상장주식 | C13: 10000000 | D13: 원 | E13: 배당가산 대상. 잘 모르면 아래 칸에 넣으세요(세금이 실제와 같거나 크게 나와요)
B14: 배당 · ETF 분배금·해외주식 등 | C14: 6000000 | D14: 원 | E14: 국내 증권사 계좌에서 세금을 떼고 받은 것
B15: 지금 건강보험 | C15: 피부양자 | E15: 직장가입자 가족의 피부양자인지, 지역가입자인지
B16: (선택) 공적연금·근로소득 | C16: 12000000 | D16: 원 | E16: 건보 계산에만 씀. 국민연금 등 1년 받은 총액. 사적연금은 넣지 않아요
B17: (선택) 그 밖의 종합소득금액 | C17: 0 | D17: 원 | E17: 세금 계산에만 씀. 종합소득세 신고서의 소득금액(이자·배당 뺀 것)
B18: (선택) 재산세 과세표준 합계 | C18: 300000000 | D18: 원 | E18: 집·땅·건물. 재산세 고지서의 과세표준(시세보다 낮아요)
B20: 근거 표 | E20: 근거
B21: ① 금융소득 종합과세 — 소득세
B22: 금융소득 합계 | C22: =(N(C12)+N(C13)+N(C14)) | D22: 원 | E22: 이자 + 배당(받은 금액, 세전)
B23: 2천만원을 넘는 금액 | C23: =MAX(0,C22-기준값!$C$6) | D23: 원 | E23: 소득세법 제14조제3항제6호
B24: 배당가산 대상 배당 가운데 넘는 부분 | C24: =MIN(N(C13),C23) | D24: 원 | E24: 이자 → 그 밖의 배당 → 국내 상장주식 배당 순으로 2천만원을 채운다(시행령 제116조의2)
B25: 배당가산액 | C25: =ROUND(C24*기준값!$C$9,0) | D25: 원 | E25: 소득세법 제17조제3항·제56조제4항
B26: 기본세율을 매기는 금액 | C26: =IF(C22>기준값!$C$6,MAX(0,C23+C25+N(C17)-기준값!$C$10),"") | D26: 원 | E26: 2천만원 초과 금융소득 + 배당가산액 + 다른 종합소득금액 − 소득공제
B27: 종합과세 시 세액 ① | C27: =IF(C22>기준값!$C$6,ROUND(기준값!$C$6*기준값!$C$7+IF((C26)<=0,0,INDEX(기준값!$C$28:$C$35,COUNTIF(기준값!$B$28:$B$35,"<"&(C26)))+((C26)-INDEX(기준값!$B$28:$B$35,COUNTIF(기준값!$B$28:$B$35,"<"&(C26))))*INDEX(기준값!$E$28:$E$35,COUNTIF(기준값!$B$28:$B$35,"<"&(C26)))),0),"") | D27: 원 | E27: 2천만원×14% + 위 금액×기본세율(제62조제1호, 국세상담센터 산식 ①)
B28: 분리과세 시 세액 ② | C28: =ROUND(N(C12)*기준값!$C$7+(N(C13)+N(C14))*기준값!$C$8+IF((MAX(0,N(C17)-기준값!$C$10))<=0,0,INDEX(기준값!$C$28:$C$35,COUNTIF(기준값!$B$28:$B$35,"<"&(MAX(0,N(C17)-기준값!$C$10))))+((MAX(0,N(C17)-기준값!$C$10))-INDEX(기준값!$B$28:$B$35,COUNTIF(기준값!$B$28:$B$35,"<"&(MAX(0,N(C17)-기준값!$C$10)))))*INDEX(기준값!$E$28:$E$35,COUNTIF(기준값!$B$28:$B$35,"<"&(MAX(0,N(C17)-기준값!$C$10))))),0) | D28: 원 | E28: 금융소득×14% + (다른 종합소득금액 − 소득공제)×기본세율(제62조제2호, 산식 ②)
B29: 배당세액공제 | C29: =IF(C22>기준값!$C$6,C25,0) | D29: 원 | E29: 소득세법 제56조제1항
B30: 세금 기준 금액 | C30: =IF(C22>기준값!$C$6,MAX(C27-C29,C28),C28) | D30: 원 | E30: (① − 배당세액공제)와 ② 가운데 큰 것(제15조제2호·제62조)
B31: 종합과세로 더 내는 소득세(연) | C31: =C30-C28 | D31: 원 | E31: 세금 기준 금액 − ②. ②는 원천징수 14%와 다른 소득 세금이라 어차피 내는 돈
B32: ② 피부양자 — 소득·재산 요건
B33: 건보 소득에 들어가는 금융소득 | C33: =IF(C22>기준값!$C$15,C22,0) | D33: 원 | E33: 1천만원 이하면 0, 넘으면 전액(시행규칙 제44조제1항 단서)
B34: 합산소득 A — 금융소득을 모두 넣으면 | C34: =C22+N(C16) | D34: 원 | E34: 공단 누리집 "모든 소득(사업·금융·연금·근로기타소득 등)을 합하여"
B35: 합산소득 B — 1천만원 이하 금융소득을 빼면 | C35: =C33+N(C16) | D35: 원 | E35: 소득월액 규칙(시행규칙 제44조제1항 단서)을 그대로 쓸 때
B36: 소득 한도 | C36: =IF(N(C18)>기준값!$C$22,기준값!$C$24,기준값!$C$21) | D36: 원 | E36: 재산 과표 5.4억원 이하 2천만원, 5.4억~9억원 1천만원(별표 1의2)
B37: 판정 A | C37: =IF(N(C18)>기준값!$C$23,"탈락",IF(C34<=C36,"유지","탈락")) | E37: 재산 과표 9억원 넘으면 탈락(별표 1의2 제2호)
B38: 판정 B | C38: =IF(N(C18)>기준값!$C$23,"탈락",IF(C35<=C36,"유지","탈락"))
B39: 피부양자 판정 | C39: =IF(C37=C38,C37,"확인 필요") | E39: A와 B가 다르면 공단(1577-1000)에 확인. 기준값 시트 "확인 필요" 첫 줄
B40: ③ 지역가입자 — 월 건강보험료
B41: 건보 소득(연) | C41: =C33+N(C16)*기준값!$C$16 | D41: 원 | E41: 금융소득(1천만원 넘을 때) + 공적연금·근로소득의 50%
B42: 소득월액 | C42: =C41/12 | D42: 원 | E42: 연간 소득 ÷ 12(국민건강보험법 제71조제2항)
B43: 소득 보험료 | C43: =IF(C42<=기준값!$C$17,기준값!$C$18,C42*기준값!$C$11) | D43: 원 | E43: 소득월액 × 7.19%. 28만원 이하면 하한 20,160원(시행규칙 제44조제3항, 고시 제3조)
B44: 재산 금액(1억원 공제 뒤) | C44: =MAX(0,N(C18)-기준값!$C$20) | D44: 원 | E44: 시행령 별표 4 제1호
...

Sheet 기준값
B2: 기준값 — 해마다 바뀌는 값은 여기만 고친다
B3: 원문은 국가법령정보센터(law.go.kr)·국민건강보험공단·국세청 누리집에서 2026-10-12에 확인했다.
B5: 항목 | C5: 값 | D5: 단위 | E5: 근거 | F5: 원문 문장 | G5: 시행·적용 | H5: 확인
B6: 종합과세기준금액 | C6: 20000000 | D6: 원 | E6: 소득세법 제14조제3항제6호 | F6: 이자소득과 배당소득으로서 그 소득의 합계액이 2천만원(이하 "이자소득등의 종합과세기준금액"이라 한다) 이하이면서 제127조에 따라 원천징수된 소득 | G6: 현행(2026.4.21 시행판) | H6: 확인함
B7: 원천징수세율 · 이자 | C7: 0.14 | E7: 소득세법 제129조제1항제1호라목 | F7: 그 밖의 이자소득에 대해서는 100분의 14 | G7: 현행(2026.4.21 시행판) | H7: 확인함
B8: 원천징수세율 · 배당 | C8: 0.14 | E8: 소득세법 제129조제1항제2호나목 | F8: 그 밖의 배당소득에 대해서는 100분의 14 | G8: 현행(2026.4.21 시행판) | H8: 확인함
B9: 배당가산율(Gross-up) | C9: 0.1 | E9: 소득세법 제17조제3항, 부칙(법률 제21221호, 2025.12.23) 제14조 | F9: 해당 과세기간의 총수입금액에 그 배당소득의 100분의 10에 해당하는 금액을 더한 금액 / 2026년 12월 31일 이전에 지급받은 배당소득의 소득금액 계산에 관하여는 … 종전의 규정에 따른다 | G9: 2026년 12월 31일까지 받는 배당. 2027.1.1부터 100분의 11(같은 부칙 제1조제2호) — 2027년 배당이면 이 칸을 11%로 바꾼다 | H9: 확인함
B10: 종합소득공제(본인 기본공제만) | C10: 1500000 | D10: 원 | E10: 소득세법 제50조제1항제1호 | F10: 1명당 연 150만원을 곱하여 계산한 금액을 그 거주자의 해당 과세기간의 종합소득금액에서 공제한다 | G10: 현행. 배우자·부양가족 공제나 다른 소득공제가 있으면 이 칸을 그 합계로 바꾼다 | H10: 확인함
B11: 건강보험료율 | C11: 0.0719 | E11: 국민건강보험법 시행령 제44조제1항 | F11: 지역가입자의 보험료율은 각각 1만분의 719로 한다 | G11: 2026년 1월분 보험료부터(시행령 부칙 2025.12.23 제2조). 2027년도 7.19% 유지 심의(정책브리핑 2026.9.8 제15차 건정심 브리핑) | H11: 확인함
B12: 재산보험료 부과점수당 금액 | C12: 211.5 | D12: 원 | E12: 국민건강보험법 시행령 제44조제2항 | F12: 지역가입자의 재산보험료부과점수당 금액은 211.5원으로 한다 | G12: 2026년 1월분 보험료부터(같은 부칙 제2조). 2027년 값은 확인 안 함 | H12: 확인함
B13: 장기요양보험료율 | C13: 0.009448 | E13: 노인장기요양보험법 시행령 제4조 | F13: 장기요양보험료율은 100만분의 9,448로 한다 | G13: 2026.5.12판 기준 | H13: 확인함
B14: 장기요양보험료 = 건보료 × 이 비율 | C14: =ROUND(기준값!$C$13/기준값!$C$11,4) | E14: 노인장기요양보험법 제9조제1항 | F14: 산정한 보험료액에서 … 건강보험료율 대비 장기요양보험료율의 비율(소수점 이하 다섯째자리에서 반올림한다)을 곱하여 산정한 금액 / 보건복지부 보도자료(2025.11.4): "2026년도 건강보험료 대비 장기요양보험료율은 13.14%" | G14: 2026.5.26판 | H14: 확인함
B15: 건보 금융소득 문턱 | C15: 10000000 | D15: 원 | E15: 국민건강보험법 시행규칙 제44조제1항 단서 | F15: 「소득세법」 제14조제3항제6호에 따른 소득이 1천만원 이하인 경우에는 해당 이자소득과 배당소득은 합산하지 않는다 | G15: 2026.9.28 시행판 | H15: 확인함
B16: 지역가입자 근로·연금소득 반영률 | C16: 0.5 | E16: 국민건강보험법 시행규칙 제44조제2항제2호·제3항 | F16: 영 제41조제1항제4호 및 제5호의 소득: 해당 소득의 100분의 50 / 지역가입자의 소득월액 산정방법에 관하여는 제2항 전단을 준용한다 | G16: 2026.9.28 시행판 | H16: 확인함
B17: 소득월액 하한 기준 | C17: 280000 | D17: 원 | E17: 국민건강보험법 시행규칙 제44조제3항 단서 | F17: 지역가입자의 소득월액이 28만원 이하인 경우에는 … 월별 보험료액의 하한액을 … 보험료율로 나누어 얻은 값을 해당 지역가입자의 소득월액으로 한다 | G17: 2026.9.28 시행판 | H17: 확인함
B18: 지역가입자 월별 보험료 하한 | C18: 20160 | D18: 원 | E18: 월별 건강보험료액의 상한과 하한에 관한 고시(보건복지부고시 제2025-222호) 제3조제2호 | F18: 지역가입자의 월별 보험료액 : 20,160원 | G18: 2026년 1월분 보험료부터(고시 부칙) | H18: 확인함
B19: 지역가입자 월별 보험료 상한 | C19: 4591740 | D19: 원 | E19: 같은 고시 제2조제2호 | F19: 직장가입자의 소득월액 보험료 및 지역가입자의 월별 보험료액 : 4,591,740원 | G19: 2026년 1월분 보험료부터(고시 부칙) | H19: 확인함
B20: 재산 공제 | C20: 100000000 | D20: 원 | E20: 국민건강보험법 시행령 별표 4 제1호 | F20: 다음 각 목의 금액을 합산한 금액에서 1억원 및 제42조의2제3항 각 호의 구분에 따른 금액을 뺀 금액을 등급별로 구분하여 산정한다 | G20: 2026.10.1 시행판 | H20: 확인함
B21: 피부양자 소득 한도 | C21: 20000000 | D21: 원 | E21: 국민건강보험법 시행규칙 별표 1의2 제1호가목 | F21: 영 제41조제1항 각 호의 소득을 같은 조 제3항의 소득자료에 따라 산정한 합계액이 연간 2천만원 이하일 것 | G21: 2026.9.28 시행판 | H21: 확인함
B22: 피부양자 재산 기준 1 | C22: 540000000 | D22: 원 | E22: 같은 별표 제2호가목2) | F22: 재산세 과세표준의 합이 5억4천만원 이하일 것 | G22: 2026.9.28 시행판 | H22: 확인함
B23: 피부양자 재산 기준 2 | C23: 900000000 | D23: 원 | E23: 같은 별표 제2호가목1) | F23: 재산세 과세표준의 합이 5억 4천만원을 초과하면서 9억원 이하이고, 영 제41조제1항 각 호에 따른 소득의 합계액이 연간 1천만원 이하일 것 | G23: 2026.9.28 시행판 | H23: 확인함
B24: 재산 5.4억~9억일 때 소득 한도 | C24: 10000000 | D24: 원 | E24: 같은 별표 제2호가목1) | F24: (위 문장) 소득의 합계액이 연간 1천만원 이하일 것 | G24: 2026.9.28 시행판 | H24: 확인함
B26: 종합소득세 기본세율 — 소득세법 제55조제1항(현행, 2026.4.21 시행판)
B27: 과세표준 초과 | C27: 기본 세액 | E27: 초과분 세율
B28: 0 | C28: 0 | E28: 0.06
B29: 14000000 | C29: 840000 | E29: 0.15
B30: 50000000 | C30: 6240000 | E30: 0.24
B31: 88000000 | C31: 15360000 | E31: 0.35
B32: 150000000 | C32: 37060000 | E32: 0.38
B33: 300000000 | C33: 94060000 | E33: 0.4
B34: 500000000 | C34: 174060000 | E34: 0.42
B35: 1000000000 | C35: 384060000 | E35: 0.45
B36: 원문 표: 1,400만원 이하 6% / 84만원+1,400만원 초과분 15% / 624만원+5,000만원 초과분 24% / 1,536만원+8,800만원 초과분 35% / 3,706만원+1억5천만원 초과분 38% / 9,406만원+3억원 초과분 40% / 1억7,406만원+5억원 초과분 42% / 3억8,406만원+10억원 초과분 45%
B38: 재산등급별 점수 — 국민건강보험법 시행령 별표 4 제3호(2026.10.1 시행판), 재산금액은 1억원을 뺀 뒤 금액
B39: 등급 | C39: 초과(원) | E39: 이하(원) | F39: 점수
B40: 1 | C40: 0 | E40: 4500000 | F40: 22
B41: 2 | C41: 4500000 | E41: 9000000 | F41: 44
B42: 3 | C42: 9000000 | E42: 13500000 | F42: 66
B43: 4 | C43: 13500000 | E43: 18000000 | F43: 97
B44: 5 | C44: 18000000 | E44: 22500000 | F44: 122
...

Sheet 설명
B2: 쓰는 법
B3: 1. 「판정」 시트 회색 칸에 1년 이자·배당(세금 떼기 전)을 넣고, 지금 건강보험 자격을 고릅니다.
B4: 2. 국민연금 같은 공적연금, 다른 종합소득, 재산세 과세표준이 있으면 (선택) 칸에 넣어요. 없으면 비워 두세요.
B5: 3. 맨 위 큰 숫자가 건보료, 그 아래 줄이 종합과세로 더 내는 소득세입니다. 계산 과정은 「근거 표」에 한 줄씩 있어요.
B7: 무엇을 계산하나
B8: · 소득세: 금융소득이 2천만원을 넘으면 (① 종합과세 시 세액 − 배당세액공제)와 (② 분리과세 시 세액) 가운데 큰 것을 냅니다. ②와의 차이를 「더 내는 소득세」로 보여 줍니다.
B9: · 피부양자: 소득 합계 2천만원(재산세 과세표준 5.4억~9억원이면 1천만원), 재산세 과세표준 9억원 기준으로 봅니다.
B10: · 지역가입자: (소득월액 × 7.19% 또는 하한 20,160원) + (재산 점수 × 211.5원), 여기에 장기요양보험료를 더합니다.
B12: 언제 반영되나
B13: · 이자·배당 같은 소득은 다음 해 11월부터 그다음 해 10월까지 건보료에 들어갑니다(국민건강보험법 시행령 제41조제3항). 예: 2026년 이자·배당 → 2027년 11월~2028년 10월.
B14: · 종합소득세는 다음 해 5월에 신고합니다.
B16: 넣지 않은 것
... B26: firemap.kr
