Workbook

Sheet 월 가계부
A1: 날짜 | B1: 항목 | C1: 금액 | D1: 분류 | E1: 확인 | G1: 월 | H1: 수입 | I1: 지출 | J1: 저축 | K1: 저축률
E2: 못 읽은 줄 표시
A3: 46235 | B3: 급여 | C3: 5000000 | D3: 수입 | E3: =IF(C3="","",IF(계산!CI3="","날짜 확인",IF(계산!CJ3="","금액 확인",""))) | G3: =IF(계산!$B$5="","",EDATE(계산!$B$5,-11)) | H3: =IF(G3="","",SUMIFS(계산!$CJ$3:$CJ$3002,$D$3:$D$3002,"수입",계산!$CI$3:$CI$3002,">="&G3,계산!$CI$3:$CI$3002,"<"&EDATE(G3,1))) | I3: =IF(G3="","",SUMIFS(계산!$CJ$3:$CJ$3002,계산!$CI$3:$CI$3002,">="&G3,계산!$CI$3:$CI$3002,"<"&EDATE(G3,1))-H3) | J3: =IF(OR(G3="",AND(H3=0,I3=0)),"",H3-I3) | K3: =IF(OR(G3="",H3=0),"",J3/H3)
A4: 46236 | B4: 생활비 | C4: 3200000 | D4: 기타상품·서비스 | E4: =IF(C4="","",IF(계산!CI4="","날짜 확인",IF(계산!CJ4="","금액 확인",""))) | G4: =IF(계산!$B$5="","",EDATE(계산!$B$5,-10)) | H4: =IF(G4="","",SUMIFS(계산!$CJ$3:$CJ$3002,$D$3:$D$3002,"수입",계산!$CI$3:$CI$3002,">="&G4,계산!$CI$3:$CI$3002,"<"&EDATE(G4,1))) | I4: =IF(G4="","",SUMIFS(계산!$CJ$3:$CJ$3002,계산!$CI$3:$CI$3002,">="&G4,계산!$CI$3:$CI$3002,"<"&EDATE(G4,1))-H4) | J4: =IF(OR(G4="",AND(H4=0,I4=0)),"",H4-I4) | K4: =IF(OR(G4="",H4=0),"",J4/H4)
A5: 46266 | B5: 급여 | C5: 5000000 | D5: 수입 | E5: =IF(C5="","",IF(계산!CI5="","날짜 확인",IF(계산!CJ5="","금액 확인",""))) | G5: =IF(계산!$B$5="","",EDATE(계산!$B$5,-9)) | H5: =IF(G5="","",SUMIFS(계산!$CJ$3:$CJ$3002,$D$3:$D$3002,"수입",계산!$CI$3:$CI$3002,">="&G5,계산!$CI$3:$CI$3002,"<"&EDATE(G5,1))) | I5: =IF(G5="","",SUMIFS(계산!$CJ$3:$CJ$3002,계산!$CI$3:$CI$3002,">="&G5,계산!$CI$3:$CI$3002,"<"&EDATE(G5,1))-H5) | J5: =IF(OR(G5="",AND(H5=0,I5=0)),"",H5-I5) | K5: =IF(OR(G5="",H5=0),"",J5/H5)
A6: 46267 | B6: 생활비 | C6: 3000000 | D6: 기타상품·서비스 | E6: =IF(C6="","",IF(계산!CI6="","날짜 확인",IF(계산!CJ6="","금액 확인",""))) | G6: =IF(계산!$B$5="","",EDATE(계산!$B$5,-8)) | H6: =IF(G6="","",SUMIFS(계산!$CJ$3:$CJ$3002,$D$3:$D$3002,"수입",계산!$CI$3:$CI$3002,">="&G6,계산!$CI$3:$CI$3002,"<"&EDATE(G6,1))) | I6: =IF(G6="","",SUMIFS(계산!$CJ$3:$CJ$3002,계산!$CI$3:$CI$3002,">="&G6,계산!$CI$3:$CI$3002,"<"&EDATE(G6,1))-H6) | J6: =IF(OR(G6="",AND(H6=0,I6=0)),"",H6-I6) | K6: =IF(OR(G6="",H6=0),"",J6/H6)
E7: =IF(C7="","",IF(계산!CI7="","날짜 확인",IF(계산!CJ7="","금액 확인",""))) | G7: =IF(계산!$B$5="","",EDATE(계산!$B$5,-7)) | H7: =IF(G7="","",SUMIFS(계산!$CJ$3:$CJ$3002,$D$3:$D$3002,"수입",계산!$CI$3:$CI$3002,">="&G7,계산!$CI$3:$CI$3002,"<"&EDATE(G7,1))) | I7: =IF(G7="","",SUMIFS(계산!$CJ$3:$CJ$3002,계산!$CI$3:$CI$3002,">="&G7,계산!$CI$3:$CI$3002,"<"&EDATE(G7,1))-H7) | J7: =IF(OR(G7="",AND(H7=0,I7=0)),"",H7-I7) | K7: =IF(OR(G7="",H7=0),"",J7/H7)
E8: =IF(C8="","",IF(계산!CI8="","날짜 확인",IF(계산!CJ8="","금액 확인",""))) | G8: =IF(계산!$B$5="","",EDATE(계산!$B$5,-6)) | H8: =IF(G8="","",SUMIFS(계산!$CJ$3:$CJ$3002,$D$3:$D$3002,"수입",계산!$CI$3:$CI$3002,">="&G8,계산!$CI$3:$CI$3002,"<"&EDATE(G8,1))) | I8: =IF(G8="","",SUMIFS(계산!$CJ$3:$CJ$3002,계산!$CI$3:$CI$3002,">="&G8,계산!$CI$3:$CI$3002,"<"&EDATE(G8,1))-H8) | J8: =IF(OR(G8="",AND(H8=0,I8=0)),"",H8-I8) | K8: =IF(OR(G8="",H8=0),"",J8/H8)
E9: =IF(C9="","",IF(계산!CI9="","날짜 확인",IF(계산!CJ9="","금액 확인",""))) | G9: =IF(계산!$B$5="","",EDATE(계산!$B$5,-5)) | H9: =IF(G9="","",SUMIFS(계산!$CJ$3:$CJ$3002,$D$3:$D$3002,"수입",계산!$CI$3:$CI$3002,">="&G9,계산!$CI$3:$CI$3002,"<"&EDATE(G9,1))) | I9: =IF(G9="","",SUMIFS(계산!$CJ$3:$CJ$3002,계산!$CI$3:$CI$3002,">="&G9,계산!$CI$3:$CI$3002,"<"&EDATE(G9,1))-H9) | J9: =IF(OR(G9="",AND(H9=0,I9=0)),"",H9-I9) | K9: =IF(OR(G9="",H9=0),"",J9/H9)
E10: =IF(C10="","",IF(계산!CI10="","날짜 확인",IF(계산!CJ10="","금액 확인",""))) | G10: =IF(계산!$B$5="","",EDATE(계산!$B$5,-4)) | H10: =IF(G10="","",SUMIFS(계산!$CJ$3:$CJ$3002,$D$3:$D$3002,"수입",계산!$CI$3:$CI$3002,">="&G10,계산!$CI$3:$CI$3002,"<"&EDATE(G10,1))) | I10: =IF(G10="","",SUMIFS(계산!$CJ$3:$CJ$3002,계산!$CI$3:$CI$3002,">="&G10,계산!$CI$3:$CI$3002,"<"&EDATE(G10,1))-H10) | J10: =IF(OR(G10="",AND(H10=0,I10=0)),"",H10-I10) | K10: =IF(OR(G10="",H10=0),"",J10/H10)
E11: =IF(C11="","",IF(계산!CI11="","날짜 확인",IF(계산!CJ11="","금액 확인",""))) | G11: =IF(계산!$B$5="","",EDATE(계산!$B$5,-3)) | H11: =IF(G11="","",SUMIFS(계산!$CJ$3:$CJ$3002,$D$3:$D$3002,"수입",계산!$CI$3:$CI$3002,">="&G11,계산!$CI$3:$CI$3002,"<"&EDATE(G11,1))) | I11: =IF(G11="","",SUMIFS(계산!$CJ$3:$CJ$3002,계산!$CI$3:$CI$3002,">="&G11,계산!$CI$3:$CI$3002,"<"&EDATE(G11,1))-H11) | J11: =IF(OR(G11="",AND(H11=0,I11=0)),"",H11-I11) | K11: =IF(OR(G11="",H11=0),"",J11/H11)
E12: =IF(C12="","",IF(계산!CI12="","날짜 확인",IF(계산!CJ12="","금액 확인",""))) | G12: =IF(계산!$B$5="","",EDATE(계산!$B$5,-2)) | H12: =IF(G12="","",SUMIFS(계산!$CJ$3:$CJ$3002,$D$3:$D$3002,"수입",계산!$CI$3:$CI$3002,">="&G12,계산!$CI$3:$CI$3002,"<"&EDATE(G12,1))) | I12: =IF(G12="","",SUMIFS(계산!$CJ$3:$CJ$3002,계산!$CI$3:$CI$3002,">="&G12,계산!$CI$3:$CI$3002,"<"&EDATE(G12,1))-H12) | J12: =IF(OR(G12="",AND(H12=0,I12=0)),"",H12-I12) | K12: =IF(OR(G12="",H12=0),"",J12/H12)
E13: =IF(C13="","",IF(계산!CI13="","날짜 확인",IF(계산!CJ13="","금액 확인",""))) | G13: =IF(계산!$B$5="","",EDATE(계산!$B$5,-1)) | H13: =IF(G13="","",SUMIFS(계산!$CJ$3:$CJ$3002,$D$3:$D$3002,"수입",계산!$CI$3:$CI$3002,">="&G13,계산!$CI$3:$CI$3002,"<"&EDATE(G13,1))) | I13: =IF(G13="","",SUMIFS(계산!$CJ$3:$CJ$3002,계산!$CI$3:$CI$3002,">="&G13,계산!$CI$3:$CI$3002,"<"&EDATE(G13,1))-H13) | J13: =IF(OR(G13="",AND(H13=0,I13=0)),"",H13-I13) | K13: =IF(OR(G13="",H13=0),"",J13/H13)
E14: =IF(C14="","",IF(계산!CI14="","날짜 확인",IF(계산!CJ14="","금액 확인",""))) | G14: =IF(계산!$B$5="","",EDATE(계산!$B$5,0)) | H14: =IF(G14="","",SUMIFS(계산!$CJ$3:$CJ$3002,$D$3:$D$3002,"수입",계산!$CI$3:$CI$3002,">="&G14,계산!$CI$3:$CI$3002,"<"&EDATE(G14,1))) | I14: =IF(G14="","",SUMIFS(계산!$CJ$3:$CJ$3002,계산!$CI$3:$CI$3002,">="&G14,계산!$CI$3:$CI$3002,"<"&EDATE(G14,1))-H14) | J14: =IF(OR(G14="",AND(H14=0,I14=0)),"",H14-I14) | K14: =IF(OR(G14="",H14=0),"",J14/H14)
E15: =IF(C15="","",IF(계산!CI15="","날짜 확인",IF(계산!CJ15="","금액 확인","")))
E16: =IF(C16="","",IF(계산!CI16="","날짜 확인",IF(계산!CJ16="","금액 확인","")))
E17: =IF(C17="","",IF(계산!CI17="","날짜 확인",IF(계산!CJ17="","금액 확인","")))
E18: =IF(C18="","",IF(계산!CI18="","날짜 확인",IF(계산!CJ18="","금액 확인","")))
E19: =IF(C19="","",IF(계산!CI19="","날짜 확인",IF(계산!CJ19="","금액 확인","")))
E20: =IF(C20="","",IF(계산!CI20="","날짜 확인",IF(계산!CJ20="","금액 확인","")))
E21: =IF(C21="","",IF(계산!CI21="","날짜 확인",IF(계산!CJ21="","금액 확인","")))
E22: =IF(C22="","",IF(계산!CI22="","날짜 확인",IF(계산!CJ22="","금액 확인","")))
E23: =IF(C23="","",IF(계산!CI23="","날짜 확인",IF(계산!CJ23="","금액 확인","")))
E24: =IF(C24="","",IF(계산!CI24="","날짜 확인",IF(계산!CJ24="","금액 확인","")))
E25: =IF(C25="","",IF(계산!CI25="","날짜 확인",IF(계산!CJ25="","금액 확인","")))
E26: =IF(C26="","",IF(계산!CI26="","날짜 확인",IF(계산!CJ26="","금액 확인","")))
... E3002: =IF(C3002="","",IF(계산!CI3002="","날짜 확인",IF(계산!CJ3002="","금액 확인","")))

Sheet 은퇴 나이
B2: =계산!B33
B3: =IF(계산!B34="","은퇴 나이","은퇴 나이 · "&계산!B34)
B4: =계산!B30
B7: =계산!B31
B8: =계산!B35
B9: 연 지출 | D9: 필요 자산 | F9: 현재 자산
B10: =계산!B6*12 | D10: =계산!B32 | F10: =D13
B12: 현재 나이 | D12: 58 | G12: 세
B13: 현재 자산 | D13: 400000000 | G13: 원
B14: 연 수익률 | D14: 4 | G14: %
B15: 물가 | D15: 3 | G15: %
B16: 국민연금(월) | D16: 1200000 | G16: 원
B18: 파이어맵 계산기와 같은 식 · firemap.kr

Sheet 설명
B2: 쓰는 법
B3: 1. 「월 가계부」에 날짜·항목·금액을 넣고 분류를 목록에서 고릅니다. 월급 같은 들어온 돈은 분류를 「수입」으로 둡니다.
B4: 2. 카드사·가계부 앱에서 내려받은 내역의 날짜·내용·금액 세 열을 A~C열에 그대로 붙여 넣을 수 있습니다. 열 순서가 다르면 순서만 맞춰 주세요.
B5: 3. 날짜는 2026-10-03 · 2026.10.03 · 2026. 10. 3. · 2026/10/03 · 2026년 10월 3일 · 20261003 · 26.10.03 모양을 읽습니다. 읽지 못한 줄은 E열에 「날짜 확인」·「금액 확인」이 뜨고 계산에서 빠집니다.
B6: 4. 「은퇴 나이」 시트에 현재 나이·현재 자산·연 수익률·물가·국민연금 다섯 칸을 넣으면, 다 지난 달 가운데 가장 최근 달의 수입·지출로 은퇴 나이를 계산합니다. 이번 달 줄은 달이 끝난 뒤에 들어갑니다.
B7: 5. 예시 줄(2026년 8~9월)은 지우고 쓰세요. 줄은 3,000줄(3~3002행)까지 셉니다. 넘으면 「은퇴 나이」 시트 맨 위에 알림이 뜹니다.
B9: 계산 가정
B10: · 최근 달 (수입 − 지출)을 은퇴할 때까지 매달 모으고, 은퇴 뒤에는 그달 지출을 매년 물가만큼 늘려 꺼내 씁니다.
B11: · 90세까지 자산이 남는 가장 이른 나이를 찾습니다(70세까지). 퇴직금·부동산·세금은 넣지 않았습니다.
B12: · 국민연금은 넣은 월 금액(지금 돈 기준)을 출생연도에 따라 60~65세부터 받는다고 보고, 물가만큼 늘립니다. 받을 금액을 모르면 0으로 두세요.
B13: · 「이번 달 지출대로면 지난달보다 N개월 빨라져요·늦어져요」는 앞뒤 두 해 결과 사이를 나눠 어림한 값입니다.
B14: · 「월 지출이 10만원 늘면 약 N개월 늦어져요」는 지출에 10만원을 더해 같은 계산을 한 번 더 한 값입니다.
... B21: firemap.kr

Sheet 계산
A1: 나이 | B1: ='은퇴 나이'!D12 | H1: 분류 목록 | CB1: y | CC1: 할인 인출 | CE1: 나이 | CF1: 자산 | CH1: 글자 날짜 | CI1: 날짜 | CJ1: 금액 | CK1: 다 지난 달 | CM1: 연 | CN1: 월 | CO1: 일
A2: 자산 | B2: ='은퇴 나이'!D13 | H2: 수입 | CB2: 1 | CC2: =IF($B$1+CB2>90,0,12*MAX(0,$B$6-IF($B$1+CB2>=$B$23,$B$22,0))*(1+$B$4)^CB2/(1+$B$3)^(CB2-1)) | CE2: =IF($B$1+0>90,NA(),$B$1+0) | CF2: =IF(OR($B$21="",$B$1+0>90),NA(),INDEX($C$40:$BU$90,$B$21-$B$1+1,1))
A3: 수익률 | B3: ='은퇴 나이'!D14/100 | H3: 식료품·비주류음료 | CB3: 2 | CC3: =IF($B$1+CB3>90,0,12*MAX(0,$B$6-IF($B$1+CB3>=$B$23,$B$22,0))*(1+$B$4)^CB3/(1+$B$3)^(CB3-1)) | CE3: =IF($B$1+1>90,NA(),$B$1+1) | CF3: =IF(OR($B$21="",$B$1+1>90),NA(),INDEX($C$40:$BU$90,$B$21-$B$1+1,2)) | CH3: =IF(ISTEXT('월 가계부'!A3),SUBSTITUTE(SUBSTITUTE(SUBSTITUTE(SUBSTITUTE(SUBSTITUTE(SUBSTITUTE(SUBSTITUTE(SUBSTITUTE(SUBSTITUTE(TRIM('월 가계부'!A3),"년","-"),"월","-"),"일",""),".","-"),"/","-")," ","-"),"--","-"),"--","-"),"--","-")&"-","") | CI3: =IFERROR(IF('월 가계부'!A3="","",IF(ISNUMBER('월 가계부'!A3),IF(AND('월 가계부'!A3>=19000101,'월 가계부'!A3<=21001231),IF(AND(MOD(INT('월 가계부'!A3/100),100)>=1,MOD(INT('월 가계부'!A3/100),100)<=12,MOD(INT('월 가계부'!A3),100)>=1,MOD(INT('월 가계부'!A3),100)<=31),IF(MONTH(DATE(INT('월 가계부'!A3/10000),MOD(INT('월 가계부'!A3/100),100),MOD(INT('월 가계부'!A3),100)))=MOD(INT('월 가계부'!A3/100),100),DATE(INT('월 가계부'!A3/10000),MOD(INT('월 가계부'!A3/100),100),MOD(INT('월 가계부'!A3),100)),""),""),IF(AND('월 가계부'!A3>=36526,'월 가계부'!A3<73051),INT('월 가계부'!A3),"")),IF(OR(CM3="",CN3="",CO3=""),"",IF(AND(CM3>=2000,CM3<=2099,CN3>=1,CN3<=12,CO3>=1,CO3<=31),IF(MONTH(DATE(CM3,CN3,CO3))=CN3,DATE(CM3,CN3,CO3),""),"")))),"") | CJ3: =IFERROR(IF('월 가계부'!C3="","",IF(ISNUMBER('월 가계부'!C3),'월 가계부'!C3,VALUE(SUBSTITUTE(SUBSTITUTE(SUBSTITUTE(SUBSTITUTE(TRIM('월 가계부'!C3),",",""),"원","")," ",""),"−","-")))),"") | CK3: =IF(ISNUMBER(CI3),IF(CI3<$B$13,CI3,""),"") | CM3: =IF(CH3="","",IFERROR(IF(IF(AND(LEN(CH3)=9,ISERROR(FIND("-",LEFT(CH3,8))),ISNUMBER(-LEFT(CH3,8))),VALUE(LEFT(CH3,4)),VALUE(LEFT(CH3,FIND("-",CH3)-1)))<100,IF(AND(LEN(CH3)=9,ISERROR(FIND("-",LEFT(CH3,8))),ISNUMBER(-LEFT(CH3,8))),VALUE(LEFT(CH3,4)),VALUE(LEFT(CH3,FIND("-",CH3)-1)))+2000,IF(AND(LEN(CH3)=9,ISERROR(FIND("-",LEFT(CH3,8))),ISNUMBER(-LEFT(CH3,8))),VALUE(LEFT(CH3,4)),VALUE(LEFT(CH3,FIND("-",CH3)-1)))),"")) | CN3: =IF(CH3="","",IFERROR(IF(AND(LEN(CH3)=9,ISERROR(FIND("-",LEFT(CH3,8))),ISNUMBER(-LEFT(CH3,8))),VALUE(MID(CH3,5,2)),VALUE(MID(CH3,FIND("-",CH3)+1,FIND("-",CH3,FIND("-",CH3)+1)-FIND("-",CH3)-1))),"")) | CO3: =IF(CH3="","",IFERROR(IF(AND(LEN(CH3)=9,ISERROR(FIND("-",LEFT(CH3,8))),ISNUMBER(-LEFT(CH3,8))),VALUE(MID(CH3,7,2)),VALUE(MID(CH3,FIND("-",CH3,FIND("-",CH3)+1)+1,FIND("-",CH3,FIND("-",CH3,FIND("-",CH3)+1)+1)-FIND("-",CH3,FIND("-",CH3)+1)-1))),""))
A4: 물가 | B4: ='은퇴 나이'!D15/100 | H4: 주류·담배 | CB4: 3 | CC4: =IF($B$1+CB4>90,0,12*MAX(0,$B$6-IF($B$1+CB4>=$B$23,$B$22,0))*(1+$B$4)^CB4/(1+$B$3)^(CB4-1)) | CE4: =IF($B$1+2>90,NA(),$B$1+2) | CF4: =IF(OR($B$21="",$B$1+2>90),NA(),INDEX($C$40:$BU$90,$B$21-$B$1+1,3)) | CH4: =IF(ISTEXT('월 가계부'!A4),SUBSTITUTE(SUBSTITUTE(SUBSTITUTE(SUBSTITUTE(SUBSTITUTE(SUBSTITUTE(SUBSTITUTE(SUBSTITUTE(SUBSTITUTE(TRIM('월 가계부'!A4),"년","-"),"월","-"),"일",""),".","-"),"/","-")," ","-"),"--","-"),"--","-"),"--","-")&"-","") | CI4: =IFERROR(IF('월 가계부'!A4="","",IF(ISNUMBER('월 가계부'!A4),IF(AND('월 가계부'!A4>=19000101,'월 가계부'!A4<=21001231),IF(AND(MOD(INT('월 가계부'!A4/100),100)>=1,MOD(INT('월 가계부'!A4/100),100)<=12,MOD(INT('월 가계부'!A4),100)>=1,MOD(INT('월 가계부'!A4),100)<=31),IF(MONTH(DATE(INT('월 가계부'!A4/10000),MOD(INT('월 가계부'!A4/100),100),MOD(INT('월 가계부'!A4),100)))=MOD(INT('월 가계부'!A4/100),100),DATE(INT('월 가계부'!A4/10000),MOD(INT('월 가계부'!A4/100),100),MOD(INT('월 가계부'!A4),100)),""),""),IF(AND('월 가계부'!A4>=36526,'월 가계부'!A4<73051),INT('월 가계부'!A4),"")),IF(OR(CM4="",CN4="",CO4=""),"",IF(AND(CM4>=2000,CM4<=2099,CN4>=1,CN4<=12,CO4>=1,CO4<=31),IF(MONTH(DATE(CM4,CN4,CO4))=CN4,DATE(CM4,CN4,CO4),""),"")))),"") | CJ4: =IFERROR(IF('월 가계부'!C4="","",IF(ISNUMBER('월 가계부'!C4),'월 가계부'!C4,VALUE(SUBSTITUTE(SUBSTITUTE(SUBSTITUTE(SUBSTITUTE(TRIM('월 가계부'!C4),",",""),"원","")," ",""),"−","-")))),"") | CK4: =IF(ISNUMBER(CI4),IF(CI4<$B$13,CI4,""),"") | CM4: =IF(CH4="","",IFERROR(IF(IF(AND(LEN(CH4)=9,ISERROR(FIND("-",LEFT(CH4,8))),ISNUMBER(-LEFT(CH4,8))),VALUE(LEFT(CH4,4)),VALUE(LEFT(CH4,FIND("-",CH4)-1)))<100,IF(AND(LEN(CH4)=9,ISERROR(FIND("-",LEFT(CH4,8))),ISNUMBER(-LEFT(CH4,8))),VALUE(LEFT(CH4,4)),VALUE(LEFT(CH4,FIND("-",CH4)-1)))+2000,IF(AND(LEN(CH4)=9,ISERROR(FIND("-",LEFT(CH4,8))),ISNUMBER(-LEFT(CH4,8))),VALUE(LEFT(CH4,4)),VALUE(LEFT(CH4,FIND("-",CH4)-1)))),"")) | CN4: =IF(CH4="","",IFERROR(IF(AND(LEN(CH4)=9,ISERROR(FIND("-",LEFT(CH4,8))),ISNUMBER(-LEFT(CH4,8))),VALUE(MID(CH4,5,2)),VALUE(MID(CH4,FIND("-",CH4)+1,FIND("-",CH4,FIND("-",CH4)+1)-FIND("-",CH4)-1))),"")) | CO4: =IF(CH4="","",IFERROR(IF(AND(LEN(CH4)=9,ISERROR(FIND("-",LEFT(CH4,8))),ISNUMBER(-LEFT(CH4,8))),VALUE(MID(CH4,7,2)),VALUE(MID(CH4,FIND("-",CH4,FIND("-",CH4)+1)+1,FIND("-",CH4,FIND("-",CH4,FIND("-",CH4)+1)+1)-FIND("-",CH4,FIND("-",CH4)+1)-1))),""))
A5: 기준 달 | B5: =IF(B15=0,"",DATE(YEAR(IF(B14>0,B14,B15)),MONTH(IF(B14>0,B14,B15)),1)) | H5: 의류·신발 | CB5: 4 | CC5: =IF($B$1+CB5>90,0,12*MAX(0,$B$6-IF($B$1+CB5>=$B$23,$B$22,0))*(1+$B$4)^CB5/(1+$B$3)^(CB5-1)) | CE5: =IF($B$1+3>90,NA(),$B$1+3) | CF5: =IF(OR($B$21="",$B$1+3>90),NA(),INDEX($C$40:$BU$90,$B$21-$B$1+1,4)) | CH5: =IF(ISTEXT('월 가계부'!A5),SUBSTITUTE(SUBSTITUTE(SUBSTITUTE(SUBSTITUTE(SUBSTITUTE(SUBSTITUTE(SUBSTITUTE(SUBSTITUTE(SUBSTITUTE(TRIM('월 가계부'!A5),"년","-"),"월","-"),"일",""),".","-"),"/","-")," ","-"),"--","-"),"--","-"),"--","-")&"-","") | CI5: =IFERROR(IF('월 가계부'!A5="","",IF(ISNUMBER('월 가계부'!A5),IF(AND('월 가계부'!A5>=19000101,'월 가계부'!A5<=21001231),IF(AND(MOD(INT('월 가계부'!A5/100),100)>=1,MOD(INT('월 가계부'!A5/100),100)<=12,MOD(INT('월 가계부'!A5),100)>=1,MOD(INT('월 가계부'!A5),100)<=31),IF(MONTH(DATE(INT('월 가계부'!A5/10000),MOD(INT('월 가계부'!A5/100),100),MOD(INT('월 가계부'!A5),100)))=MOD(INT('월 가계부'!A5/100),100),DATE(INT('월 가계부'!A5/10000),MOD(INT('월 가계부'!A5/100),100),MOD(INT('월 가계부'!A5),100)),""),""),IF(AND('월 가계부'!A5>=36526,'월 가계부'!A5<73051),INT('월 가계부'!A5),"")),IF(OR(CM5="",CN5="",CO5=""),"",IF(AND(CM5>=2000,CM5<=2099,CN5>=1,CN5<=12,CO5>=1,CO5<=31),IF(MONTH(DATE(CM5,CN5,CO5))=CN5,DATE(CM5,CN5,CO5),""),"")))),"") | CJ5: =IFERROR(IF('월 가계부'!C5="","",IF(ISNUMBER('월 가계부'!C5),'월 가계부'!C5,VALUE(SUBSTITUTE(SUBSTITUTE(SUBSTITUTE(SUBSTITUTE(TRIM('월 가계부'!C5),",",""),"원","")," ",""),"−","-")))),"") | CK5: =IF(ISNUMBER(CI5),IF(CI5<$B$13,CI5,""),"") | CM5: =IF(CH5="","",IFERROR(IF(IF(AND(LEN(CH5)=9,ISERROR(FIND("-",LEFT(CH5,8))),ISNUMBER(-LEFT(CH5,8))),VALUE(LEFT(CH5,4)),VALUE(LEFT(CH5,FIND("-",CH5)-1)))<100,IF(AND(LEN(CH5)=9,ISERROR(FIND("-",LEFT(CH5,8))),ISNUMBER(-LEFT(CH5,8))),VALUE(LEFT(CH5,4)),VALUE(LEFT(CH5,FIND("-",CH5)-1)))+2000,IF(AND(LEN(CH5)=9,ISERROR(FIND("-",LEFT(CH5,8))),ISNUMBER(-LEFT(CH5,8))),VALUE(LEFT(CH5,4)),VALUE(LEFT(CH5,FIND("-",CH5)-1)))),"")) | CN5: =IF(CH5="","",IFERROR(IF(AND(LEN(CH5)=9,ISERROR(FIND("-",LEFT(CH5,8))),ISNUMBER(-LEFT(CH5,8))),VALUE(MID(CH5,5,2)),VALUE(MID(CH5,FIND("-",CH5)+1,FIND("-",CH5,FIND("-",CH5)+1)-FIND("-",CH5)-1))),"")) | CO5: =IF(CH5="","",IFERROR(IF(AND(LEN(CH5)=9,ISERROR(FIND("-",LEFT(CH5,8))),ISNUMBER(-LEFT(CH5,8))),VALUE(MID(CH5,7,2)),VALUE(MID(CH5,FIND("-",CH5,FIND("-",CH5)+1)+1,FIND("-",CH5,FIND("-",CH5,FIND("-",CH5)+1)+1)-FIND("-",CH5,FIND("-",CH5)+1)-1))),""))
A6: 이번 달 지출 | B6: =IF(B5="",0,N(INDEX('월 가계부'!$I$3:$I$14,12))) | H6: 주거·수도·광열 | CB6: 5 | CC6: =IF($B$1+CB6>90,0,12*MAX(0,$B$6-IF($B$1+CB6>=$B$23,$B$22,0))*(1+$B$4)^CB6/(1+$B$3)^(CB6-1)) | CE6: =IF($B$1+4>90,NA(),$B$1+4) | CF6: =IF(OR($B$21="",$B$1+4>90),NA(),INDEX($C$40:$BU$90,$B$21-$B$1+1,5)) | CH6: =IF(ISTEXT('월 가계부'!A6),SUBSTITUTE(SUBSTITUTE(SUBSTITUTE(SUBSTITUTE(SUBSTITUTE(SUBSTITUTE(SUBSTITUTE(SUBSTITUTE(SUBSTITUTE(TRIM('월 가계부'!A6),"년","-"),"월","-"),"일",""),".","-"),"/","-")," ","-"),"--","-"),"--","-"),"--","-")&"-","") | CI6: =IFERROR(IF('월 가계부'!A6="","",IF(ISNUMBER('월 가계부'!A6),IF(AND('월 가계부'!A6>=19000101,'월 가계부'!A6<=21001231),IF(AND(MOD(INT('월 가계부'!A6/100),100)>=1,MOD(INT('월 가계부'!A6/100),100)<=12,MOD(INT('월 가계부'!A6),100)>=1,MOD(INT('월 가계부'!A6),100)<=31),IF(MONTH(DATE(INT('월 가계부'!A6/10000),MOD(INT('월 가계부'!A6/100),100),MOD(INT('월 가계부'!A6),100)))=MOD(INT('월 가계부'!A6/100),100),DATE(INT('월 가계부'!A6/10000),MOD(INT('월 가계부'!A6/100),100),MOD(INT('월 가계부'!A6),100)),""),""),IF(AND('월 가계부'!A6>=36526,'월 가계부'!A6<73051),INT('월 가계부'!A6),"")),IF(OR(CM6="",CN6="",CO6=""),"",IF(AND(CM6>=2000,CM6<=2099,CN6>=1,CN6<=12,CO6>=1,CO6<=31),IF(MONTH(DATE(CM6,CN6,CO6))=CN6,DATE(CM6,CN6,CO6),""),"")))),"") | CJ6: =IFERROR(IF('월 가계부'!C6="","",IF(ISNUMBER('월 가계부'!C6),'월 가계부'!C6,VALUE(SUBSTITUTE(SUBSTITUTE(SUBSTITUTE(SUBSTITUTE(TRIM('월 가계부'!C6),",",""),"원","")," ",""),"−","-")))),"") | CK6: =IF(ISNUMBER(CI6),IF(CI6<$B$13,CI6,""),"") | CM6: =IF(CH6="","",IFERROR(IF(IF(AND(LEN(CH6)=9,ISERROR(FIND("-",LEFT(CH6,8))),ISNUMBER(-LEFT(CH6,8))),VALUE(LEFT(CH6,4)),VALUE(LEFT(CH6,FIND("-",CH6)-1)))<100,IF(AND(LEN(CH6)=9,ISERROR(FIND("-",LEFT(CH6,8))),ISNUMBER(-LEFT(CH6,8))),VALUE(LEFT(CH6,4)),VALUE(LEFT(CH6,FIND("-",CH6)-1)))+2000,IF(AND(LEN(CH6)=9,ISERROR(FIND("-",LEFT(CH6,8))),ISNUMBER(-LEFT(CH6,8))),VALUE(LEFT(CH6,4)),VALUE(LEFT(CH6,FIND("-",CH6)-1)))),"")) | CN6: =IF(CH6="","",IFERROR(IF(AND(LEN(CH6)=9,ISERROR(FIND("-",LEFT(CH6,8))),ISNUMBER(-LEFT(CH6,8))),VALUE(MID(CH6,5,2)),VALUE(MID(CH6,FIND("-",CH6)+1,FIND("-",CH6,FIND("-",CH6)+1)-FIND("-",CH6)-1))),"")) | CO6: =IF(CH6="","",IFERROR(IF(AND(LEN(CH6)=9,ISERROR(FIND("-",LEFT(CH6,8))),ISNUMBER(-LEFT(CH6,8))),VALUE(MID(CH6,7,2)),VALUE(MID(CH6,FIND("-",CH6,FIND("-",CH6)+1)+1,FIND("-",CH6,FIND("-",CH6,FIND("-",CH6)+1)+1)-FIND("-",CH6,FIND("-",CH6)+1)-1))),""))
A7: 이번 달 저축 | B7: =IF(B5="",0,N(INDEX('월 가계부'!$J$3:$J$14,12))) | H7: 가정용품·가사서비스 | CB7: 6 | CC7: =IF($B$1+CB7>90,0,12*MAX(0,$B$6-IF($B$1+CB7>=$B$23,$B$22,0))*(1+$B$4)^CB7/(1+$B$3)^(CB7-1)) | CE7: =IF($B$1+5>90,NA(),$B$1+5) | CF7: =IF(OR($B$21="",$B$1+5>90),NA(),INDEX($C$40:$BU$90,$B$21-$B$1+1,6)) | CH7: =IF(ISTEXT('월 가계부'!A7),SUBSTITUTE(SUBSTITUTE(SUBSTITUTE(SUBSTITUTE(SUBSTITUTE(SUBSTITUTE(SUBSTITUTE(SUBSTITUTE(SUBSTITUTE(TRIM('월 가계부'!A7),"년","-"),"월","-"),"일",""),".","-"),"/","-")," ","-"),"--","-"),"--","-"),"--","-")&"-","") | CI7: =IFERROR(IF('월 가계부'!A7="","",IF(ISNUMBER('월 가계부'!A7),IF(AND('월 가계부'!A7>=19000101,'월 가계부'!A7<=21001231),IF(AND(MOD(INT('월 가계부'!A7/100),100)>=1,MOD(INT('월 가계부'!A7/100),100)<=12,MOD(INT('월 가계부'!A7),100)>=1,MOD(INT('월 가계부'!A7),100)<=31),IF(MONTH(DATE(INT('월 가계부'!A7/10000),MOD(INT('월 가계부'!A7/100),100),MOD(INT('월 가계부'!A7),100)))=MOD(INT('월 가계부'!A7/100),100),DATE(INT('월 가계부'!A7/10000),MOD(INT('월 가계부'!A7/100),100),MOD(INT('월 가계부'!A7),100)),""),""),IF(AND('월 가계부'!A7>=36526,'월 가계부'!A7<73051),INT('월 가계부'!A7),"")),IF(OR(CM7="",CN7="",CO7=""),"",IF(AND(CM7>=2000,CM7<=2099,CN7>=1,CN7<=12,CO7>=1,CO7<=31),IF(MONTH(DATE(CM7,CN7,CO7))=CN7,DATE(CM7,CN7,CO7),""),"")))),"") | CJ7: =IFERROR(IF('월 가계부'!C7="","",IF(ISNUMBER('월 가계부'!C7),'월 가계부'!C7,VALUE(SUBSTITUTE(SUBSTITUTE(SUBSTITUTE(SUBSTITUTE(TRIM('월 가계부'!C7),",",""),"원","")," ",""),"−","-")))),"") | CK7: =IF(ISNUMBER(CI7),IF(CI7<$B$13,CI7,""),"") | CM7: =IF(CH7="","",IFERROR(IF(IF(AND(LEN(CH7)=9,ISERROR(FIND("-",LEFT(CH7,8))),ISNUMBER(-LEFT(CH7,8))),VALUE(LEFT(CH7,4)),VALUE(LEFT(CH7,FIND("-",CH7)-1)))<100,IF(AND(LEN(CH7)=9,ISERROR(FIND("-",LEFT(CH7,8))),ISNUMBER(-LEFT(CH7,8))),VALUE(LEFT(CH7,4)),VALUE(LEFT(CH7,FIND("-",CH7)-1)))+2000,IF(AND(LEN(CH7)=9,ISERROR(FIND("-",LEFT(CH7,8))),ISNUMBER(-LEFT(CH7,8))),VALUE(LEFT(CH7,4)),VALUE(LEFT(CH7,FIND("-",CH7)-1)))),"")) | CN7: =IF(CH7="","",IFERROR(IF(AND(LEN(CH7)=9,ISERROR(FIND("-",LEFT(CH7,8))),ISNUMBER(-LEFT(CH7,8))),VALUE(MID(CH7,5,2)),VALUE(MID(CH7,FIND("-",CH7)+1,FIND("-",CH7,FIND("-",CH7)+1)-FIND("-",CH7)-1))),"")) | CO7: =IF(CH7="","",IFERROR(IF(AND(LEN(CH7)=9,ISERROR(FIND("-",LEFT(CH7,8))),ISNUMBER(-LEFT(CH7,8))),VALUE(MID(CH7,7,2)),VALUE(MID(CH7,FIND("-",CH7,FIND("-",CH7)+1)+1,FIND("-",CH7,FIND("-",CH7,FIND("-",CH7)+1)+1)-FIND("-",CH7,FIND("-",CH7)+1)-1))),""))
A8: 지난달 지출 | B8: =IF(B5="",0,N(INDEX('월 가계부'!$I$3:$I$14,11))) | H8: 보건 | CB8: 7 | CC8: =IF($B$1+CB8>90,0,12*MAX(0,$B$6-IF($B$1+CB8>=$B$23,$B$22,0))*(1+$B$4)^CB8/(1+$B$3)^(CB8-1)) | CE8: =IF($B$1+6>90,NA(),$B$1+6) | CF8: =IF(OR($B$21="",$B$1+6>90),NA(),INDEX($C$40:$BU$90,$B$21-$B$1+1,7)) | CH8: =IF(ISTEXT('월 가계부'!A8),SUBSTITUTE(SUBSTITUTE(SUBSTITUTE(SUBSTITUTE(SUBSTITUTE(SUBSTITUTE(SUBSTITUTE(SUBSTITUTE(SUBSTITUTE(TRIM('월 가계부'!A8),"년","-"),"월","-"),"일",""),".","-"),"/","-")," ","-"),"--","-"),"--","-"),"--","-")&"-","") | CI8: =IFERROR(IF('월 가계부'!A8="","",IF(ISNUMBER('월 가계부'!A8),IF(AND('월 가계부'!A8>=19000101,'월 가계부'!A8<=21001231),IF(AND(MOD(INT('월 가계부'!A8/100),100)>=1,MOD(INT('월 가계부'!A8/100),100)<=12,MOD(INT('월 가계부'!A8),100)>=1,MOD(INT('월 가계부'!A8),100)<=31),IF(MONTH(DATE(INT('월 가계부'!A8/10000),MOD(INT('월 가계부'!A8/100),100),MOD(INT('월 가계부'!A8),100)))=MOD(INT('월 가계부'!A8/100),100),DATE(INT('월 가계부'!A8/10000),MOD(INT('월 가계부'!A8/100),100),MOD(INT('월 가계부'!A8),100)),""),""),IF(AND('월 가계부'!A8>=36526,'월 가계부'!A8<73051),INT('월 가계부'!A8),"")),IF(OR(CM8="",CN8="",CO8=""),"",IF(AND(CM8>=2000,CM8<=2099,CN8>=1,CN8<=12,CO8>=1,CO8<=31),IF(MONTH(DATE(CM8,CN8,CO8))=CN8,DATE(CM8,CN8,CO8),""),"")))),"") | CJ8: =IFERROR(IF('월 가계부'!C8="","",IF(ISNUMBER('월 가계부'!C8),'월 가계부'!C8,VALUE(SUBSTITUTE(SUBSTITUTE(SUBSTITUTE(SUBSTITUTE(TRIM('월 가계부'!C8),",",""),"원","")," ",""),"−","-")))),"") | CK8: =IF(ISNUMBER(CI8),IF(CI8<$B$13,CI8,""),"") | CM8: =IF(CH8="","",IFERROR(IF(IF(AND(LEN(CH8)=9,ISERROR(FIND("-",LEFT(CH8,8))),ISNUMBER(-LEFT(CH8,8))),VALUE(LEFT(CH8,4)),VALUE(LEFT(CH8,FIND("-",CH8)-1)))<100,IF(AND(LEN(CH8)=9,ISERROR(FIND("-",LEFT(CH8,8))),ISNUMBER(-LEFT(CH8,8))),VALUE(LEFT(CH8,4)),VALUE(LEFT(CH8,FIND("-",CH8)-1)))+2000,IF(AND(LEN(CH8)=9,ISERROR(FIND("-",LEFT(CH8,8))),ISNUMBER(-LEFT(CH8,8))),VALUE(LEFT(CH8,4)),VALUE(LEFT(CH8,FIND("-",CH8)-1)))),"")) | CN8: =IF(CH8="","",IFERROR(IF(AND(LEN(CH8)=9,ISERROR(FIND("-",LEFT(CH8,8))),ISNUMBER(-LEFT(CH8,8))),VALUE(MID(CH8,5,2)),VALUE(MID(CH8,FIND("-",CH8)+1,FIND("-",CH8,FIND("-",CH8)+1)-FIND("-",CH8)-1))),"")) | CO8: =IF(CH8="","",IFERROR(IF(AND(LEN(CH8)=9,ISERROR(FIND("-",LEFT(CH8,8))),ISNUMBER(-LEFT(CH8,8))),VALUE(MID(CH8,7,2)),VALUE(MID(CH8,FIND("-",CH8,FIND("-",CH8)+1)+1,FIND("-",CH8,FIND("-",CH8,FIND("-",CH8)+1)+1)-FIND("-",CH8,FIND("-",CH8)+1)-1))),""))
A9: 지난달 저축 | B9: =IF(B5="",0,N(INDEX('월 가계부'!$J$3:$J$14,11))) | H9: 교통 | CB9: 8 | CC9: =IF($B$1+CB9>90,0,12*MAX(0,$B$6-IF($B$1+CB9>=$B$23,$B$22,0))*(1+$B$4)^CB9/(1+$B$3)^(CB9-1)) | CE9: =IF($B$1+7>90,NA(),$B$1+7) | CF9: =IF(OR($B$21="",$B$1+7>90),NA(),INDEX($C$40:$BU$90,$B$21-$B$1+1,8)) | CH9: =IF(ISTEXT('월 가계부'!A9),SUBSTITUTE(SUBSTITUTE(SUBSTITUTE(SUBSTITUTE(SUBSTITUTE(SUBSTITUTE(SUBSTITUTE(SUBSTITUTE(SUBSTITUTE(TRIM('월 가계부'!A9),"년","-"),"월","-"),"일",""),".","-"),"/","-")," ","-"),"--","-"),"--","-"),"--","-")&"-","") | CI9: =IFERROR(IF('월 가계부'!A9="","",IF(ISNUMBER('월 가계부'!A9),IF(AND('월 가계부'!A9>=19000101,'월 가계부'!A9<=21001231),IF(AND(MOD(INT('월 가계부'!A9/100),100)>=1,MOD(INT('월 가계부'!A9/100),100)<=12,MOD(INT('월 가계부'!A9),100)>=1,MOD(INT('월 가계부'!A9),100)<=31),IF(MONTH(DATE(INT('월 가계부'!A9/10000),MOD(INT('월 가계부'!A9/100),100),MOD(INT('월 가계부'!A9),100)))=MOD(INT('월 가계부'!A9/100),100),DATE(INT('월 가계부'!A9/10000),MOD(INT('월 가계부'!A9/100),100),MOD(INT('월 가계부'!A9),100)),""),""),IF(AND('월 가계부'!A9>=36526,'월 가계부'!A9<73051),INT('월 가계부'!A9),"")),IF(OR(CM9="",CN9="",CO9=""),"",IF(AND(CM9>=2000,CM9<=2099,CN9>=1,CN9<=12,CO9>=1,CO9<=31),IF(MONTH(DATE(CM9,CN9,CO9))=CN9,DATE(CM9,CN9,CO9),""),"")))),"") | CJ9: =IFERROR(IF('월 가계부'!C9="","",IF(ISNUMBER('월 가계부'!C9),'월 가계부'!C9,VALUE(SUBSTITUTE(SUBSTITUTE(SUBSTITUTE(SUBSTITUTE(TRIM('월 가계부'!C9),",",""),"원","")," ",""),"−","-")))),"") | CK9: =IF(ISNUMBER(CI9),IF(CI9<$B$13,CI9,""),"") | CM9: =IF(CH9="","",IFERROR(IF(IF(AND(LEN(CH9)=9,ISERROR(FIND("-",LEFT(CH9,8))),ISNUMBER(-LEFT(CH9,8))),VALUE(LEFT(CH9,4)),VALUE(LEFT(CH9,FIND("-",CH9)-1)))<100,IF(AND(LEN(CH9)=9,ISERROR(FIND("-",LEFT(CH9,8))),ISNUMBER(-LEFT(CH9,8))),VALUE(LEFT(CH9,4)),VALUE(LEFT(CH9,FIND("-",CH9)-1)))+2000,IF(AND(LEN(CH9)=9,ISERROR(FIND("-",LEFT(CH9,8))),ISNUMBER(-LEFT(CH9,8))),VALUE(LEFT(CH9,4)),VALUE(LEFT(CH9,FIND("-",CH9)-1)))),"")) | CN9: =IF(CH9="","",IFERROR(IF(AND(LEN(CH9)=9,ISERROR(FIND("-",LEFT(CH9,8))),ISNUMBER(-LEFT(CH9,8))),VALUE(MID(CH9,5,2)),VALUE(MID(CH9,FIND("-",CH9)+1,FIND("-",CH9,FIND("-",CH9)+1)-FIND("-",CH9)-1))),"")) | CO9: =IF(CH9="","",IFERROR(IF(AND(LEN(CH9)=9,ISERROR(FIND("-",LEFT(CH9,8))),ISNUMBER(-LEFT(CH9,8))),VALUE(MID(CH9,7,2)),VALUE(MID(CH9,FIND("-",CH9,FIND("-",CH9)+1)+1,FIND("-",CH9,FIND("-",CH9,FIND("-",CH9)+1)+1)-FIND("-",CH9,FIND("-",CH9)+1)-1))),""))
A10: 기울기 증가분 | B10: 100000 | H10: 통신 | CB10: 9 | CC10: =IF($B$1+CB10>90,0,12*MAX(0,$B$6-IF($B$1+CB10>=$B$23,$B$22,0))*(1+$B$4)^CB10/(1+$B$3)^(CB10-1)) | CE10: =IF($B$1+8>90,NA(),$B$1+8) | CF10: =IF(OR($B$21="",$B$1+8>90),NA(),INDEX($C$40:$BU$90,$B$21-$B$1+1,9)) | CH10: =IF(ISTEXT('월 가계부'!A10),SUBSTITUTE(SUBSTITUTE(SUBSTITUTE(SUBSTITUTE(SUBSTITUTE(SUBSTITUTE(SUBSTITUTE(SUBSTITUTE(SUBSTITUTE(TRIM('월 가계부'!A10),"년","-"),"월","-"),"일",""),".","-"),"/","-")," ","-"),"--","-"),"--","-"),"--","-")&"-","") | CI10: =IFERROR(IF('월 가계부'!A10="","",IF(ISNUMBER('월 가계부'!A10),IF(AND('월 가계부'!A10>=19000101,'월 가계부'!A10<=21001231),IF(AND(MOD(INT('월 가계부'!A10/100),100)>=1,MOD(INT('월 가계부'!A10/100),100)<=12,MOD(INT('월 가계부'!A10),100)>=1,MOD(INT('월 가계부'!A10),100)<=31),IF(MONTH(DATE(INT('월 가계부'!A10/10000),MOD(INT('월 가계부'!A10/100),100),MOD(INT('월 가계부'!A10),100)))=MOD(INT('월 가계부'!A10/100),100),DATE(INT('월 가계부'!A10/10000),MOD(INT('월 가계부'!A10/100),100),MOD(INT('월 가계부'!A10),100)),""),""),IF(AND('월 가계부'!A10>=36526,'월 가계부'!A10<73051),INT('월 가계부'!A10),"")),IF(OR(CM10="",CN10="",CO10=""),"",IF(AND(CM10>=2000,CM10<=2099,CN10>=1,CN10<=12,CO10>=1,CO10<=31),IF(MONTH(DATE(CM10,CN10,CO10))=CN10,DATE(CM10,CN10,CO10),""),"")))),"") | CJ10: =IFERROR(IF('월 가계부'!C10="","",IF(ISNUMBER('월 가계부'!C10),'월 가계부'!C10,VALUE(SUBSTITUTE(SUBSTITUTE(SUBSTITUTE(SUBSTITUTE(TRIM('월 가계부'!C10),",",""),"원","")," ",""),"−","-")))),"") | CK10: =IF(ISNUMBER(CI10),IF(CI10<$B$13,CI10,""),"") | CM10: =IF(CH10="","",IFERROR(IF(IF(AND(LEN(CH10)=9,ISERROR(FIND("-",LEFT(CH10,8))),ISNUMBER(-LEFT(CH10,8))),VALUE(LEFT(CH10,4)),VALUE(LEFT(CH10,FIND("-",CH10)-1)))<100,IF(AND(LEN(CH10)=9,ISERROR(FIND("-",LEFT(CH10,8))),ISNUMBER(-LEFT(CH10,8))),VALUE(LEFT(CH10,4)),VALUE(LEFT(CH10,FIND("-",CH10)-1)))+2000,IF(AND(LEN(CH10)=9,ISERROR(FIND("-",LEFT(CH10,8))),ISNUMBER(-LEFT(CH10,8))),VALUE(LEFT(CH10,4)),VALUE(LEFT(CH10,FIND("-",CH10)-1)))),"")) | CN10: =IF(CH10="","",IFERROR(IF(AND(LEN(CH10)=9,ISERROR(FIND("-",LEFT(CH10,8))),ISNUMBER(-LEFT(CH10,8))),VALUE(MID(CH10,5,2)),VALUE(MID(CH10,FIND("-",CH10)+1,FIND("-",CH10,FIND("-",CH10)+1)-FIND("-",CH10)-1))),"")) | CO10: =IF(CH10="","",IFERROR(IF(AND(LEN(CH10)=9,ISERROR(FIND("-",LEFT(CH10,8))),ISNUMBER(-LEFT(CH10,8))),VALUE(MID(CH10,7,2)),VALUE(MID(CH10,FIND("-",CH10,FIND("-",CH10)+1)+1,FIND("-",CH10,FIND("-",CH10,FIND("-",CH10)+1)+1)-FIND("-",CH10,FIND("-",CH10)+1)-1))),""))
H11: 오락·문화 | CB11: 10 | CC11: =IF($B$1+CB11>90,0,12*MAX(0,$B$6-IF($B$1+CB11>=$B$23,$B$22,0))*(1+$B$4)^CB11/(1+$B$3)^(CB11-1)) | CE11: =IF($B$1+9>90,NA(),$B$1+9) | CF11: =IF(OR($B$21="",$B$1+9>90),NA(),INDEX($C$40:$BU$90,$B$21-$B$1+1,10)) | CH11: =IF(ISTEXT('월 가계부'!A11),SUBSTITUTE(SUBSTITUTE(SUBSTITUTE(SUBSTITUTE(SUBSTITUTE(SUBSTITUTE(SUBSTITUTE(SUBSTITUTE(SUBSTITUTE(TRIM('월 가계부'!A11),"년","-"),"월","-"),"일",""),".","-"),"/","-")," ","-"),"--","-"),"--","-"),"--","-")&"-","") | CI11: =IFERROR(IF('월 가계부'!A11="","",IF(ISNUMBER('월 가계부'!A11),IF(AND('월 가계부'!A11>=19000101,'월 가계부'!A11<=21001231),IF(AND(MOD(INT('월 가계부'!A11/100),100)>=1,MOD(INT('월 가계부'!A11/100),100)<=12,MOD(INT('월 가계부'!A11),100)>=1,MOD(INT('월 가계부'!A11),100)<=31),IF(MONTH(DATE(INT('월 가계부'!A11/10000),MOD(INT('월 가계부'!A11/100),100),MOD(INT('월 가계부'!A11),100)))=MOD(INT('월 가계부'!A11/100),100),DATE(INT('월 가계부'!A11/10000),MOD(INT('월 가계부'!A11/100),100),MOD(INT('월 가계부'!A11),100)),""),""),IF(AND('월 가계부'!A11>=36526,'월 가계부'!A11<73051),INT('월 가계부'!A11),"")),IF(OR(CM11="",CN11="",CO11=""),"",IF(AND(CM11>=2000,CM11<=2099,CN11>=1,CN11<=12,CO11>=1,CO11<=31),IF(MONTH(DATE(CM11,CN11,CO11))=CN11,DATE(CM11,CN11,CO11),""),"")))),"") | CJ11: =IFERROR(IF('월 가계부'!C11="","",IF(ISNUMBER('월 가계부'!C11),'월 가계부'!C11,VALUE(SUBSTITUTE(SUBSTITUTE(SUBSTITUTE(SUBSTITUTE(TRIM('월 가계부'!C11),",",""),"원","")," ",""),"−","-")))),"") | CK11: =IF(ISNUMBER(CI11),IF(CI11<$B$13,CI11,""),"") | CM11: =IF(CH11="","",IFERROR(IF(IF(AND(LEN(CH11)=9,ISERROR(FIND("-",LEFT(CH11,8))),ISNUMBER(-LEFT(CH11,8))),VALUE(LEFT(CH11,4)),VALUE(LEFT(CH11,FIND("-",CH11)-1)))<100,IF(AND(LEN(CH11)=9,ISERROR(FIND("-",LEFT(CH11,8))),ISNUMBER(-LEFT(CH11,8))),VALUE(LEFT(CH11,4)),VALUE(LEFT(CH11,FIND("-",CH11)-1)))+2000,IF(AND(LEN(CH11)=9,ISERROR(FIND("-",LEFT(CH11,8))),ISNUMBER(-LEFT(CH11,8))),VALUE(LEFT(CH11,4)),VALUE(LEFT(CH11,FIND("-",CH11)-1)))),"")) | CN11: =IF(CH11="","",IFERROR(IF(AND(LEN(CH11)=9,ISERROR(FIND("-",LEFT(CH11,8))),ISNUMBER(-LEFT(CH11,8))),VALUE(MID(CH11,5,2)),VALUE(MID(CH11,FIND("-",CH11)+1,FIND("-",CH11,FIND("-",CH11)+1)-FIND("-",CH11)-1))),"")) | CO11: =IF(CH11="","",IFERROR(IF(AND(LEN(CH11)=9,ISERROR(FIND("-",LEFT(CH11,8))),ISNUMBER(-LEFT(CH11,8))),VALUE(MID(CH11,7,2)),VALUE(MID(CH11,FIND("-",CH11,FIND("-",CH11)+1)+1,FIND("-",CH11,FIND("-",CH11,FIND("-",CH11)+1)+1)-FIND("-",CH11,FIND("-",CH11)+1)-1))),""))
H12: 교육 | CB12: 11 | CC12: =IF($B$1+CB12>90,0,12*MAX(0,$B$6-IF($B$1+CB12>=$B$23,$B$22,0))*(1+$B$4)^CB12/(1+$B$3)^(CB12-1)) | CE12: =IF($B$1+10>90,NA(),$B$1+10) | CF12: =IF(OR($B$21="",$B$1+10>90),NA(),INDEX($C$40:$BU$90,$B$21-$B$1+1,11)) | CH12: =IF(ISTEXT('월 가계부'!A12),SUBSTITUTE(SUBSTITUTE(SUBSTITUTE(SUBSTITUTE(SUBSTITUTE(SUBSTITUTE(SUBSTITUTE(SUBSTITUTE(SUBSTITUTE(TRIM('월 가계부'!A12),"년","-"),"월","-"),"일",""),".","-"),"/","-")," ","-"),"--","-"),"--","-"),"--","-")&"-","") | CI12: =IFERROR(IF('월 가계부'!A12="","",IF(ISNUMBER('월 가계부'!A12),IF(AND('월 가계부'!A12>=19000101,'월 가계부'!A12<=21001231),IF(AND(MOD(INT('월 가계부'!A12/100),100)>=1,MOD(INT('월 가계부'!A12/100),100)<=12,MOD(INT('월 가계부'!A12),100)>=1,MOD(INT('월 가계부'!A12),100)<=31),IF(MONTH(DATE(INT('월 가계부'!A12/10000),MOD(INT('월 가계부'!A12/100),100),MOD(INT('월 가계부'!A12),100)))=MOD(INT('월 가계부'!A12/100),100),DATE(INT('월 가계부'!A12/10000),MOD(INT('월 가계부'!A12/100),100),MOD(INT('월 가계부'!A12),100)),""),""),IF(AND('월 가계부'!A12>=36526,'월 가계부'!A12<73051),INT('월 가계부'!A12),"")),IF(OR(CM12="",CN12="",CO12=""),"",IF(AND(CM12>=2000,CM12<=2099,CN12>=1,CN12<=12,CO12>=1,CO12<=31),IF(MONTH(DATE(CM12,CN12,CO12))=CN12,DATE(CM12,CN12,CO12),""),"")))),"") | CJ12: =IFERROR(IF('월 가계부'!C12="","",IF(ISNUMBER('월 가계부'!C12),'월 가계부'!C12,VALUE(SUBSTITUTE(SUBSTITUTE(SUBSTITUTE(SUBSTITUTE(TRIM('월 가계부'!C12),",",""),"원","")," ",""),"−","-")))),"") | CK12: =IF(ISNUMBER(CI12),IF(CI12<$B$13,CI12,""),"") | CM12: =IF(CH12="","",IFERROR(IF(IF(AND(LEN(CH12)=9,ISERROR(FIND("-",LEFT(CH12,8))),ISNUMBER(-LEFT(CH12,8))),VALUE(LEFT(CH12,4)),VALUE(LEFT(CH12,FIND("-",CH12)-1)))<100,IF(AND(LEN(CH12)=9,ISERROR(FIND("-",LEFT(CH12,8))),ISNUMBER(-LEFT(CH12,8))),VALUE(LEFT(CH12,4)),VALUE(LEFT(CH12,FIND("-",CH12)-1)))+2000,IF(AND(LEN(CH12)=9,ISERROR(FIND("-",LEFT(CH12,8))),ISNUMBER(-LEFT(CH12,8))),VALUE(LEFT(CH12,4)),VALUE(LEFT(CH12,FIND("-",CH12)-1)))),"")) | CN12: =IF(CH12="","",IFERROR(IF(AND(LEN(CH12)=9,ISERROR(FIND("-",LEFT(CH12,8))),ISNUMBER(-LEFT(CH12,8))),VALUE(MID(CH12,5,2)),VALUE(MID(CH12,FIND("-",CH12)+1,FIND("-",CH12,FIND("-",CH12)+1)-FIND("-",CH12)-1))),"")) | CO12: =IF(CH12="","",IFERROR(IF(AND(LEN(CH12)=9,ISERROR(FIND("-",LEFT(CH12,8))),ISNUMBER(-LEFT(CH12,8))),VALUE(MID(CH12,7,2)),VALUE(MID(CH12,FIND("-",CH12,FIND("-",CH12)+1)+1,FIND("-",CH12,FIND("-",CH12,FIND("-",CH12)+1)+1)-FIND("-",CH12,FIND("-",CH12)+1)-1))),""))
A13: 이번 달 1일 | B13: =DATE(YEAR(TODAY()),MONTH(TODAY()),1) | H13: 음식·숙박 | CB13: 12 | CC13: =IF($B$1+CB13>90,0,12*MAX(0,$B$6-IF($B$1+CB13>=$B$23,$B$22,0))*(1+$B$4)^CB13/(1+$B$3)^(CB13-1)) | CE13: =IF($B$1+11>90,NA(),$B$1+11) | CF13: =IF(OR($B$21="",$B$1+11>90),NA(),INDEX($C$40:$BU$90,$B$21-$B$1+1,12)) | CH13: =IF(ISTEXT('월 가계부'!A13),SUBSTITUTE(SUBSTITUTE(SUBSTITUTE(SUBSTITUTE(SUBSTITUTE(SUBSTITUTE(SUBSTITUTE(SUBSTITUTE(SUBSTITUTE(TRIM('월 가계부'!A13),"년","-"),"월","-"),"일",""),".","-"),"/","-")," ","-"),"--","-"),"--","-"),"--","-")&"-","") | CI13: =IFERROR(IF('월 가계부'!A13="","",IF(ISNUMBER('월 가계부'!A13),IF(AND('월 가계부'!A13>=19000101,'월 가계부'!A13<=21001231),IF(AND(MOD(INT('월 가계부'!A13/100),100)>=1,MOD(INT('월 가계부'!A13/100),100)<=12,MOD(INT('월 가계부'!A13),100)>=1,MOD(INT('월 가계부'!A13),100)<=31),IF(MONTH(DATE(INT('월 가계부'!A13/10000),MOD(INT('월 가계부'!A13/100),100),MOD(INT('월 가계부'!A13),100)))=MOD(INT('월 가계부'!A13/100),100),DATE(INT('월 가계부'!A13/10000),MOD(INT('월 가계부'!A13/100),100),MOD(INT('월 가계부'!A13),100)),""),""),IF(AND('월 가계부'!A13>=36526,'월 가계부'!A13<73051),INT('월 가계부'!A13),"")),IF(OR(CM13="",CN13="",CO13=""),"",IF(AND(CM13>=2000,CM13<=2099,CN13>=1,CN13<=12,CO13>=1,CO13<=31),IF(MONTH(DATE(CM13,CN13,CO13))=CN13,DATE(CM13,CN13,CO13),""),"")))),"") | CJ13: =IFERROR(IF('월 가계부'!C13="","",IF(ISNUMBER('월 가계부'!C13),'월 가계부'!C13,VALUE(SUBSTITUTE(SUBSTITUTE(SUBSTITUTE(SUBSTITUTE(TRIM('월 가계부'!C13),",",""),"원","")," ",""),"−","-")))),"") | CK13: =IF(ISNUMBER(CI13),IF(CI13<$B$13,CI13,""),"") | CM13: =IF(CH13="","",IFERROR(IF(IF(AND(LEN(CH13)=9,ISERROR(FIND("-",LEFT(CH13,8))),ISNUMBER(-LEFT(CH13,8))),VALUE(LEFT(CH13,4)),VALUE(LEFT(CH13,FIND("-",CH13)-1)))<100,IF(AND(LEN(CH13)=9,ISERROR(FIND("-",LEFT(CH13,8))),ISNUMBER(-LEFT(CH13,8))),VALUE(LEFT(CH13,4)),VALUE(LEFT(CH13,FIND("-",CH13)-1)))+2000,IF(AND(LEN(CH13)=9,ISERROR(FIND("-",LEFT(CH13,8))),ISNUMBER(-LEFT(CH13,8))),VALUE(LEFT(CH13,4)),VALUE(LEFT(CH13,FIND("-",CH13)-1)))),"")) | CN13: =IF(CH13="","",IFERROR(IF(AND(LEN(CH13)=9,ISERROR(FIND("-",LEFT(CH13,8))),ISNUMBER(-LEFT(CH13,8))),VALUE(MID(CH13,5,2)),VALUE(MID(CH13,FIND("-",CH13)+1,FIND("-",CH13,FIND("-",CH13)+1)-FIND("-",CH13)-1))),"")) | CO13: =IF(CH13="","",IFERROR(IF(AND(LEN(CH13)=9,ISERROR(FIND("-",LEFT(CH13,8))),ISNUMBER(-LEFT(CH13,8))),VALUE(MID(CH13,7,2)),VALUE(MID(CH13,FIND("-",CH13,FIND("-",CH13)+1)+1,FIND("-",CH13,FIND("-",CH13,FIND("-",CH13)+1)+1)-FIND("-",CH13,FIND("-",CH13)+1)-1))),""))
A14: 다 지난 달 마지막 날짜 | B14: =MAX($CK$3:$CK$3002) | H14: 기타상품·서비스 | CB14: 13 | CC14: =IF($B$1+CB14>90,0,12*MAX(0,$B$6-IF($B$1+CB14>=$B$23,$B$22,0))*(1+$B$4)^CB14/(1+$B$3)^(CB14-1)) | CE14: =IF($B$1+12>90,NA(),$B$1+12) | CF14: =IF(OR($B$21="",$B$1+12>90),NA(),INDEX($C$40:$BU$90,$B$21-$B$1+1,13)) | CH14: =IF(ISTEXT('월 가계부'!A14),SUBSTITUTE(SUBSTITUTE(SUBSTITUTE(SUBSTITUTE(SUBSTITUTE(SUBSTITUTE(SUBSTITUTE(SUBSTITUTE(SUBSTITUTE(TRIM('월 가계부'!A14),"년","-"),"월","-"),"일",""),".","-"),"/","-")," ","-"),"--","-"),"--","-"),"--","-")&"-","") | CI14: =IFERROR(IF('월 가계부'!A14="","",IF(ISNUMBER('월 가계부'!A14),IF(AND('월 가계부'!A14>=19000101,'월 가계부'!A14<=21001231),IF(AND(MOD(INT('월 가계부'!A14/100),100)>=1,MOD(INT('월 가계부'!A14/100),100)<=12,MOD(INT('월 가계부'!A14),100)>=1,MOD(INT('월 가계부'!A14),100)<=31),IF(MONTH(DATE(INT('월 가계부'!A14/10000),MOD(INT('월 가계부'!A14/100),100),MOD(INT('월 가계부'!A14),100)))=MOD(INT('월 가계부'!A14/100),100),DATE(INT('월 가계부'!A14/10000),MOD(INT('월 가계부'!A14/100),100),MOD(INT('월 가계부'!A14),100)),""),""),IF(AND('월 가계부'!A14>=36526,'월 가계부'!A14<73051),INT('월 가계부'!A14),"")),IF(OR(CM14="",CN14="",CO14=""),"",IF(AND(CM14>=2000,CM14<=2099,CN14>=1,CN14<=12,CO14>=1,CO14<=31),IF(MONTH(DATE(CM14,CN14,CO14))=CN14,DATE(CM14,CN14,CO14),""),"")))),"") | CJ14: =IFERROR(IF('월 가계부'!C14="","",IF(ISNUMBER('월 가계부'!C14),'월 가계부'!C14,VALUE(SUBSTITUTE(SUBSTITUTE(SUBSTITUTE(SUBSTITUTE(TRIM('월 가계부'!C14),",",""),"원","")," ",""),"−","-")))),"") | CK14: =IF(ISNUMBER(CI14),IF(CI14<$B$13,CI14,""),"") | CM14: =IF(CH14="","",IFERROR(IF(IF(AND(LEN(CH14)=9,ISERROR(FIND("-",LEFT(CH14,8))),ISNUMBER(-LEFT(CH14,8))),VALUE(LEFT(CH14,4)),VALUE(LEFT(CH14,FIND("-",CH14)-1)))<100,IF(AND(LEN(CH14)=9,ISERROR(FIND("-",LEFT(CH14,8))),ISNUMBER(-LEFT(CH14,8))),VALUE(LEFT(CH14,4)),VALUE(LEFT(CH14,FIND("-",CH14)-1)))+2000,IF(AND(LEN(CH14)=9,ISERROR(FIND("-",LEFT(CH14,8))),ISNUMBER(-LEFT(CH14,8))),VALUE(LEFT(CH14,4)),VALUE(LEFT(CH14,FIND("-",CH14)-1)))),"")) | CN14: =IF(CH14="","",IFERROR(IF(AND(LEN(CH14)=9,ISERROR(FIND("-",LEFT(CH14,8))),ISNUMBER(-LEFT(CH14,8))),VALUE(MID(CH14,5,2)),VALUE(MID(CH14,FIND("-",CH14)+1,FIND("-",CH14,FIND("-",CH14)+1)-FIND("-",CH14)-1))),"")) | CO14: =IF(CH14="","",IFERROR(IF(AND(LEN(CH14)=9,ISERROR(FIND("-",LEFT(CH14,8))),ISNUMBER(-LEFT(CH14,8))),VALUE(MID(CH14,7,2)),VALUE(MID(CH14,FIND("-",CH14,FIND("-",CH14)+1)+1,FIND("-",CH14,FIND("-",CH14,FIND("-",CH14)+1)+1)-FIND("-",CH14,FIND("-",CH14)+1)-1))),""))
A15: 마지막 날짜 | B15: =MAX($CI$3:$CI$3002) | CB15: 14 | CC15: =IF($B$1+CB15>90,0,12*MAX(0,$B$6-IF($B$1+CB15>=$B$23,$B$22,0))*(1+$B$4)^CB15/(1+$B$3)^(CB15-1)) | CE15: =IF($B$1+13>90,NA(),$B$1+13) | CF15: =IF(OR($B$21="",$B$1+13>90),NA(),INDEX($C$40:$BU$90,$B$21-$B$1+1,14)) | CH15: =IF(ISTEXT('월 가계부'!A15),SUBSTITUTE(SUBSTITUTE(SUBSTITUTE(SUBSTITUTE(SUBSTITUTE(SUBSTITUTE(SUBSTITUTE(SUBSTITUTE(SUBSTITUTE(TRIM('월 가계부'!A15),"년","-"),"월","-"),"일",""),".","-"),"/","-")," ","-"),"--","-"),"--","-"),"--","-")&"-","") | CI15: =IFERROR(IF('월 가계부'!A15="","",IF(ISNUMBER('월 가계부'!A15),IF(AND('월 가계부'!A15>=19000101,'월 가계부'!A15<=21001231),IF(AND(MOD(INT('월 가계부'!A15/100),100)>=1,MOD(INT('월 가계부'!A15/100),100)<=12,MOD(INT('월 가계부'!A15),100)>=1,MOD(INT('월 가계부'!A15),100)<=31),IF(MONTH(DATE(INT('월 가계부'!A15/10000),MOD(INT('월 가계부'!A15/100),100),MOD(INT('월 가계부'!A15),100)))=MOD(INT('월 가계부'!A15/100),100),DATE(INT('월 가계부'!A15/10000),MOD(INT('월 가계부'!A15/100),100),MOD(INT('월 가계부'!A15),100)),""),""),IF(AND('월 가계부'!A15>=36526,'월 가계부'!A15<73051),INT('월 가계부'!A15),"")),IF(OR(CM15="",CN15="",CO15=""),"",IF(AND(CM15>=2000,CM15<=2099,CN15>=1,CN15<=12,CO15>=1,CO15<=31),IF(MONTH(DATE(CM15,CN15,CO15))=CN15,DATE(CM15,CN15,CO15),""),"")))),"") | CJ15: =IFERROR(IF('월 가계부'!C15="","",IF(ISNUMBER('월 가계부'!C15),'월 가계부'!C15,VALUE(SUBSTITUTE(SUBSTITUTE(SUBSTITUTE(SUBSTITUTE(TRIM('월 가계부'!C15),",",""),"원","")," ",""),"−","-")))),"") | CK15: =IF(ISNUMBER(CI15),IF(CI15<$B$13,CI15,""),"") | CM15: =IF(CH15="","",IFERROR(IF(IF(AND(LEN(CH15)=9,ISERROR(FIND("-",LEFT(CH15,8))),ISNUMBER(-LEFT(CH15,8))),VALUE(LEFT(CH15,4)),VALUE(LEFT(CH15,FIND("-",CH15)-1)))<100,IF(AND(LEN(CH15)=9,ISERROR(FIND("-",LEFT(CH15,8))),ISNUMBER(-LEFT(CH15,8))),VALUE(LEFT(CH15,4)),VALUE(LEFT(CH15,FIND("-",CH15)-1)))+2000,IF(AND(LEN(CH15)=9,ISERROR(FIND("-",LEFT(CH15,8))),ISNUMBER(-LEFT(CH15,8))),VALUE(LEFT(CH15,4)),VALUE(LEFT(CH15,FIND("-",CH15)-1)))),"")) | CN15: =IF(CH15="","",IFERROR(IF(AND(LEN(CH15)=9,ISERROR(FIND("-",LEFT(CH15,8))),ISNUMBER(-LEFT(CH15,8))),VALUE(MID(CH15,5,2)),VALUE(MID(CH15,FIND("-",CH15)+1,FIND("-",CH15,FIND("-",CH15)+1)-FIND("-",CH15)-1))),"")) | CO15: =IF(CH15="","",IFERROR(IF(AND(LEN(CH15)=9,ISERROR(FIND("-",LEFT(CH15,8))),ISNUMBER(-LEFT(CH15,8))),VALUE(MID(CH15,7,2)),VALUE(MID(CH15,FIND("-",CH15,FIND("-",CH15)+1)+1,FIND("-",CH15,FIND("-",CH15,FIND("-",CH15)+1)+1)-FIND("-",CH15,FIND("-",CH15)+1)-1))),""))
A16: 안 끝난 달로 계산 | B16: =AND(B14=0,B15>0) | CB16: 15 | CC16: =IF($B$1+CB16>90,0,12*MAX(0,$B$6-IF($B$1+CB16>=$B$23,$B$22,0))*(1+$B$4)^CB16/(1+$B$3)^(CB16-1)) | CE16: =IF($B$1+14>90,NA(),$B$1+14) | CF16: =IF(OR($B$21="",$B$1+14>90),NA(),INDEX($C$40:$BU$90,$B$21-$B$1+1,15)) | CH16: =IF(ISTEXT('월 가계부'!A16),SUBSTITUTE(SUBSTITUTE(SUBSTITUTE(SUBSTITUTE(SUBSTITUTE(SUBSTITUTE(SUBSTITUTE(SUBSTITUTE(SUBSTITUTE(TRIM('월 가계부'!A16),"년","-"),"월","-"),"일",""),".","-"),"/","-")," ","-"),"--","-"),"--","-"),"--","-")&"-","") | CI16: =IFERROR(IF('월 가계부'!A16="","",IF(ISNUMBER('월 가계부'!A16),IF(AND('월 가계부'!A16>=19000101,'월 가계부'!A16<=21001231),IF(AND(MOD(INT('월 가계부'!A16/100),100)>=1,MOD(INT('월 가계부'!A16/100),100)<=12,MOD(INT('월 가계부'!A16),100)>=1,MOD(INT('월 가계부'!A16),100)<=31),IF(MONTH(DATE(INT('월 가계부'!A16/10000),MOD(INT('월 가계부'!A16/100),100),MOD(INT('월 가계부'!A16),100)))=MOD(INT('월 가계부'!A16/100),100),DATE(INT('월 가계부'!A16/10000),MOD(INT('월 가계부'!A16/100),100),MOD(INT('월 가계부'!A16),100)),""),""),IF(AND('월 가계부'!A16>=36526,'월 가계부'!A16<73051),INT('월 가계부'!A16),"")),IF(OR(CM16="",CN16="",CO16=""),"",IF(AND(CM16>=2000,CM16<=2099,CN16>=1,CN16<=12,CO16>=1,CO16<=31),IF(MONTH(DATE(CM16,CN16,CO16))=CN16,DATE(CM16,CN16,CO16),""),"")))),"") | CJ16: =IFERROR(IF('월 가계부'!C16="","",IF(ISNUMBER('월 가계부'!C16),'월 가계부'!C16,VALUE(SUBSTITUTE(SUBSTITUTE(SUBSTITUTE(SUBSTITUTE(TRIM('월 가계부'!C16),",",""),"원","")," ",""),"−","-")))),"") | CK16: =IF(ISNUMBER(CI16),IF(CI16<$B$13,CI16,""),"") | CM16: =IF(CH16="","",IFERROR(IF(IF(AND(LEN(CH16)=9,ISERROR(FIND("-",LEFT(CH16,8))),ISNUMBER(-LEFT(CH16,8))),VALUE(LEFT(CH16,4)),VALUE(LEFT(CH16,FIND("-",CH16)-1)))<100,IF(AND(LEN(CH16)=9,ISERROR(FIND("-",LEFT(CH16,8))),ISNUMBER(-LEFT(CH16,8))),VALUE(LEFT(CH16,4)),VALUE(LEFT(CH16,FIND("-",CH16)-1)))+2000,IF(AND(LEN(CH16)=9,ISERROR(FIND("-",LEFT(CH16,8))),ISNUMBER(-LEFT(CH16,8))),VALUE(LEFT(CH16,4)),VALUE(LEFT(CH16,FIND("-",CH16)-1)))),"")) | CN16: =IF(CH16="","",IFERROR(IF(AND(LEN(CH16)=9,ISERROR(FIND("-",LEFT(CH16,8))),ISNUMBER(-LEFT(CH16,8))),VALUE(MID(CH16,5,2)),VALUE(MID(CH16,FIND("-",CH16)+1,FIND("-",CH16,FIND("-",CH16)+1)-FIND("-",CH16)-1))),"")) | CO16: =IF(CH16="","",IFERROR(IF(AND(LEN(CH16)=9,ISERROR(FIND("-",LEFT(CH16,8))),ISNUMBER(-LEFT(CH16,8))),VALUE(MID(CH16,7,2)),VALUE(MID(CH16,FIND("-",CH16,FIND("-",CH16)+1)+1,FIND("-",CH16,FIND("-",CH16,FIND("-",CH16)+1)+1)-FIND("-",CH16,FIND("-",CH16)+1)-1))),""))
A17: 이번 달부터 줄 수 | B17: =COUNTIF($CI$3:$CI$3002,">="&B13) | CB17: 16 | CC17: =IF($B$1+CB17>90,0,12*MAX(0,$B$6-IF($B$1+CB17>=$B$23,$B$22,0))*(1+$B$4)^CB17/(1+$B$3)^(CB17-1)) | CE17: =IF($B$1+15>90,NA(),$B$1+15) | CF17: =IF(OR($B$21="",$B$1+15>90),NA(),INDEX($C$40:$BU$90,$B$21-$B$1+1,16)) | CH17: =IF(ISTEXT('월 가계부'!A17),SUBSTITUTE(SUBSTITUTE(SUBSTITUTE(SUBSTITUTE(SUBSTITUTE(SUBSTITUTE(SUBSTITUTE(SUBSTITUTE(SUBSTITUTE(TRIM('월 가계부'!A17),"년","-"),"월","-"),"일",""),".","-"),"/","-")," ","-"),"--","-"),"--","-"),"--","-")&"-","") | CI17: =IFERROR(IF('월 가계부'!A17="","",IF(ISNUMBER('월 가계부'!A17),IF(AND('월 가계부'!A17>=19000101,'월 가계부'!A17<=21001231),IF(AND(MOD(INT('월 가계부'!A17/100),100)>=1,MOD(INT('월 가계부'!A17/100),100)<=12,MOD(INT('월 가계부'!A17),100)>=1,MOD(INT('월 가계부'!A17),100)<=31),IF(MONTH(DATE(INT('월 가계부'!A17/10000),MOD(INT('월 가계부'!A17/100),100),MOD(INT('월 가계부'!A17),100)))=MOD(INT('월 가계부'!A17/100),100),DATE(INT('월 가계부'!A17/10000),MOD(INT('월 가계부'!A17/100),100),MOD(INT('월 가계부'!A17),100)),""),""),IF(AND('월 가계부'!A17>=36526,'월 가계부'!A17<73051),INT('월 가계부'!A17),"")),IF(OR(CM17="",CN17="",CO17=""),"",IF(AND(CM17>=2000,CM17<=2099,CN17>=1,CN17<=12,CO17>=1,CO17<=31),IF(MONTH(DATE(CM17,CN17,CO17))=CN17,DATE(CM17,CN17,CO17),""),"")))),"") | CJ17: =IFERROR(IF('월 가계부'!C17="","",IF(ISNUMBER('월 가계부'!C17),'월 가계부'!C17,VALUE(SUBSTITUTE(SUBSTITUTE(SUBSTITUTE(SUBSTITUTE(TRIM('월 가계부'!C17),",",""),"원","")," ",""),"−","-")))),"") | CK17: =IF(ISNUMBER(CI17),IF(CI17<$B$13,CI17,""),"") | CM17: =IF(CH17="","",IFERROR(IF(IF(AND(LEN(CH17)=9,ISERROR(FIND("-",LEFT(CH17,8))),ISNUMBER(-LEFT(CH17,8))),VALUE(LEFT(CH17,4)),VALUE(LEFT(CH17,FIND("-",CH17)-1)))<100,IF(AND(LEN(CH17)=9,ISERROR(FIND("-",LEFT(CH17,8))),ISNUMBER(-LEFT(CH17,8))),VALUE(LEFT(CH17,4)),VALUE(LEFT(CH17,FIND("-",CH17)-1)))+2000,IF(AND(LEN(CH17)=9,ISERROR(FIND("-",LEFT(CH17,8))),ISNUMBER(-LEFT(CH17,8))),VALUE(LEFT(CH17,4)),VALUE(LEFT(CH17,FIND("-",CH17)-1)))),"")) | CN17: =IF(CH17="","",IFERROR(IF(AND(LEN(CH17)=9,ISERROR(FIND("-",LEFT(CH17,8))),ISNUMBER(-LEFT(CH17,8))),VALUE(MID(CH17,5,2)),VALUE(MID(CH17,FIND("-",CH17)+1,FIND("-",CH17,FIND("-",CH17)+1)-FIND("-",CH17)-1))),"")) | CO17: =IF(CH17="","",IFERROR(IF(AND(LEN(CH17)=9,ISERROR(FIND("-",LEFT(CH17,8))),ISNUMBER(-LEFT(CH17,8))),VALUE(MID(CH17,7,2)),VALUE(MID(CH17,FIND("-",CH17,FIND("-",CH17)+1)+1,FIND("-",CH17,FIND("-",CH17,FIND("-",CH17)+1)+1)-FIND("-",CH17,FIND("-",CH17)+1)-1))),""))
A18: 못 읽은 줄 수 | B18: =COUNTIF('월 가계부'!$E$3:$E$3002,"날짜 확인")+COUNTIF('월 가계부'!$E$3:$E$3002,"금액 확인") | CB18: 17 | CC18: =IF($B$1+CB18>90,0,12*MAX(0,$B$6-IF($B$1+CB18>=$B$23,$B$22,0))*(1+$B$4)^CB18/(1+$B$3)^(CB18-1)) | CE18: =IF($B$1+16>90,NA(),$B$1+16) | CF18: =IF(OR($B$21="",$B$1+16>90),NA(),INDEX($C$40:$BU$90,$B$21-$B$1+1,17)) | CH18: =IF(ISTEXT('월 가계부'!A18),SUBSTITUTE(SUBSTITUTE(SUBSTITUTE(SUBSTITUTE(SUBSTITUTE(SUBSTITUTE(SUBSTITUTE(SUBSTITUTE(SUBSTITUTE(TRIM('월 가계부'!A18),"년","-"),"월","-"),"일",""),".","-"),"/","-")," ","-"),"--","-"),"--","-"),"--","-")&"-","") | CI18: =IFERROR(IF('월 가계부'!A18="","",IF(ISNUMBER('월 가계부'!A18),IF(AND('월 가계부'!A18>=19000101,'월 가계부'!A18<=21001231),IF(AND(MOD(INT('월 가계부'!A18/100),100)>=1,MOD(INT('월 가계부'!A18/100),100)<=12,MOD(INT('월 가계부'!A18),100)>=1,MOD(INT('월 가계부'!A18),100)<=31),IF(MONTH(DATE(INT('월 가계부'!A18/10000),MOD(INT('월 가계부'!A18/100),100),MOD(INT('월 가계부'!A18),100)))=MOD(INT('월 가계부'!A18/100),100),DATE(INT('월 가계부'!A18/10000),MOD(INT('월 가계부'!A18/100),100),MOD(INT('월 가계부'!A18),100)),""),""),IF(AND('월 가계부'!A18>=36526,'월 가계부'!A18<73051),INT('월 가계부'!A18),"")),IF(OR(CM18="",CN18="",CO18=""),"",IF(AND(CM18>=2000,CM18<=2099,CN18>=1,CN18<=12,CO18>=1,CO18<=31),IF(MONTH(DATE(CM18,CN18,CO18))=CN18,DATE(CM18,CN18,CO18),""),"")))),"") | CJ18: =IFERROR(IF('월 가계부'!C18="","",IF(ISNUMBER('월 가계부'!C18),'월 가계부'!C18,VALUE(SUBSTITUTE(SUBSTITUTE(SUBSTITUTE(SUBSTITUTE(TRIM('월 가계부'!C18),",",""),"원","")," ",""),"−","-")))),"") | CK18: =IF(ISNUMBER(CI18),IF(CI18<$B$13,CI18,""),"") | CM18: =IF(CH18="","",IFERROR(IF(IF(AND(LEN(CH18)=9,ISERROR(FIND("-",LEFT(CH18,8))),ISNUMBER(-LEFT(CH18,8))),VALUE(LEFT(CH18,4)),VALUE(LEFT(CH18,FIND("-",CH18)-1)))<100,IF(AND(LEN(CH18)=9,ISERROR(FIND("-",LEFT(CH18,8))),ISNUMBER(-LEFT(CH18,8))),VALUE(LEFT(CH18,4)),VALUE(LEFT(CH18,FIND("-",CH18)-1)))+2000,IF(AND(LEN(CH18)=9,ISERROR(FIND("-",LEFT(CH18,8))),ISNUMBER(-LEFT(CH18,8))),VALUE(LEFT(CH18,4)),VALUE(LEFT(CH18,FIND("-",CH18)-1)))),"")) | CN18: =IF(CH18="","",IFERROR(IF(AND(LEN(CH18)=9,ISERROR(FIND("-",LEFT(CH18,8))),ISNUMBER(-LEFT(CH18,8))),VALUE(MID(CH18,5,2)),VALUE(MID(CH18,FIND("-",CH18)+1,FIND("-",CH18,FIND("-",CH18)+1)-FIND("-",CH18)-1))),"")) | CO18: =IF(CH18="","",IFERROR(IF(AND(LEN(CH18)=9,ISERROR(FIND("-",LEFT(CH18,8))),ISNUMBER(-LEFT(CH18,8))),VALUE(MID(CH18,7,2)),VALUE(MID(CH18,FIND("-",CH18,FIND("-",CH18)+1)+1,FIND("-",CH18,FIND("-",CH18,FIND("-",CH18)+1)+1)-FIND("-",CH18,FIND("-",CH18)+1)-1))),""))
A19: 3,000줄 밖 줄 수 | B19: =SUMPRODUCT(--((('월 가계부'!$A$3003:$A$13002<>"")+('월 가계부'!$C$3003:$C$13002<>""))>0)) | CB19: 18 | CC19: =IF($B$1+CB19>90,0,12*MAX(0,$B$6-IF($B$1+CB19>=$B$23,$B$22,0))*(1+$B$4)^CB19/(1+$B$3)^(CB19-1)) | CE19: =IF($B$1+17>90,NA(),$B$1+17) | CF19: =IF(OR($B$21="",$B$1+17>90),NA(),INDEX($C$40:$BU$90,$B$21-$B$1+1,18)) | CH19: =IF(ISTEXT('월 가계부'!A19),SUBSTITUTE(SUBSTITUTE(SUBSTITUTE(SUBSTITUTE(SUBSTITUTE(SUBSTITUTE(SUBSTITUTE(SUBSTITUTE(SUBSTITUTE(TRIM('월 가계부'!A19),"년","-"),"월","-"),"일",""),".","-"),"/","-")," ","-"),"--","-"),"--","-"),"--","-")&"-","") | CI19: =IFERROR(IF('월 가계부'!A19="","",IF(ISNUMBER('월 가계부'!A19),IF(AND('월 가계부'!A19>=19000101,'월 가계부'!A19<=21001231),IF(AND(MOD(INT('월 가계부'!A19/100),100)>=1,MOD(INT('월 가계부'!A19/100),100)<=12,MOD(INT('월 가계부'!A19),100)>=1,MOD(INT('월 가계부'!A19),100)<=31),IF(MONTH(DATE(INT('월 가계부'!A19/10000),MOD(INT('월 가계부'!A19/100),100),MOD(INT('월 가계부'!A19),100)))=MOD(INT('월 가계부'!A19/100),100),DATE(INT('월 가계부'!A19/10000),MOD(INT('월 가계부'!A19/100),100),MOD(INT('월 가계부'!A19),100)),""),""),IF(AND('월 가계부'!A19>=36526,'월 가계부'!A19<73051),INT('월 가계부'!A19),"")),IF(OR(CM19="",CN19="",CO19=""),"",IF(AND(CM19>=2000,CM19<=2099,CN19>=1,CN19<=12,CO19>=1,CO19<=31),IF(MONTH(DATE(CM19,CN19,CO19))=CN19,DATE(CM19,CN19,CO19),""),"")))),"") | CJ19: =IFERROR(IF('월 가계부'!C19="","",IF(ISNUMBER('월 가계부'!C19),'월 가계부'!C19,VALUE(SUBSTITUTE(SUBSTITUTE(SUBSTITUTE(SUBSTITUTE(TRIM('월 가계부'!C19),",",""),"원","")," ",""),"−","-")))),"") | CK19: =IF(ISNUMBER(CI19),IF(CI19<$B$13,CI19,""),"") | CM19: =IF(CH19="","",IFERROR(IF(IF(AND(LEN(CH19)=9,ISERROR(FIND("-",LEFT(CH19,8))),ISNUMBER(-LEFT(CH19,8))),VALUE(LEFT(CH19,4)),VALUE(LEFT(CH19,FIND("-",CH19)-1)))<100,IF(AND(LEN(CH19)=9,ISERROR(FIND("-",LEFT(CH19,8))),ISNUMBER(-LEFT(CH19,8))),VALUE(LEFT(CH19,4)),VALUE(LEFT(CH19,FIND("-",CH19)-1)))+2000,IF(AND(LEN(CH19)=9,ISERROR(FIND("-",LEFT(CH19,8))),ISNUMBER(-LEFT(CH19,8))),VALUE(LEFT(CH19,4)),VALUE(LEFT(CH19,FIND("-",CH19)-1)))),"")) | CN19: =IF(CH19="","",IFERROR(IF(AND(LEN(CH19)=9,ISERROR(FIND("-",LEFT(CH19,8))),ISNUMBER(-LEFT(CH19,8))),VALUE(MID(CH19,5,2)),VALUE(MID(CH19,FIND("-",CH19)+1,FIND("-",CH19,FIND("-",CH19)+1)-FIND("-",CH19)-1))),"")) | CO19: =IF(CH19="","",IFERROR(IF(AND(LEN(CH19)=9,ISERROR(FIND("-",LEFT(CH19,8))),ISNUMBER(-LEFT(CH19,8))),VALUE(MID(CH19,7,2)),VALUE(MID(CH19,FIND("-",CH19,FIND("-",CH19)+1)+1,FIND("-",CH19,FIND("-",CH19,FIND("-",CH19)+1)+1)-FIND("-",CH19,FIND("-",CH19)+1)-1))),""))
A20: +N일 기울기(일/원) | B20: =IF(OR(C37="",C93=""),"",(C93-C37)*365/$B$10) | CB20: 19 | CC20: =IF($B$1+CB20>90,0,12*MAX(0,$B$6-IF($B$1+CB20>=$B$23,$B$22,0))*(1+$B$4)^CB20/(1+$B$3)^(CB20-1)) | CE20: =IF($B$1+18>90,NA(),$B$1+18) | CF20: =IF(OR($B$21="",$B$1+18>90),NA(),INDEX($C$40:$BU$90,$B$21-$B$1+1,19)) | CH20: =IF(ISTEXT('월 가계부'!A20),SUBSTITUTE(SUBSTITUTE(SUBSTITUTE(SUBSTITUTE(SUBSTITUTE(SUBSTITUTE(SUBSTITUTE(SUBSTITUTE(SUBSTITUTE(TRIM('월 가계부'!A20),"년","-"),"월","-"),"일",""),".","-"),"/","-")," ","-"),"--","-"),"--","-"),"--","-")&"-","") | CI20: =IFERROR(IF('월 가계부'!A20="","",IF(ISNUMBER('월 가계부'!A20),IF(AND('월 가계부'!A20>=19000101,'월 가계부'!A20<=21001231),IF(AND(MOD(INT('월 가계부'!A20/100),100)>=1,MOD(INT('월 가계부'!A20/100),100)<=12,MOD(INT('월 가계부'!A20),100)>=1,MOD(INT('월 가계부'!A20),100)<=31),IF(MONTH(DATE(INT('월 가계부'!A20/10000),MOD(INT('월 가계부'!A20/100),100),MOD(INT('월 가계부'!A20),100)))=MOD(INT('월 가계부'!A20/100),100),DATE(INT('월 가계부'!A20/10000),MOD(INT('월 가계부'!A20/100),100),MOD(INT('월 가계부'!A20),100)),""),""),IF(AND('월 가계부'!A20>=36526,'월 가계부'!A20<73051),INT('월 가계부'!A20),"")),IF(OR(CM20="",CN20="",CO20=""),"",IF(AND(CM20>=2000,CM20<=2099,CN20>=1,CN20<=12,CO20>=1,CO20<=31),IF(MONTH(DATE(CM20,CN20,CO20))=CN20,DATE(CM20,CN20,CO20),""),"")))),"") | CJ20: =IFERROR(IF('월 가계부'!C20="","",IF(ISNUMBER('월 가계부'!C20),'월 가계부'!C20,VALUE(SUBSTITUTE(SUBSTITUTE(SUBSTITUTE(SUBSTITUTE(TRIM('월 가계부'!C20),",",""),"원","")," ",""),"−","-")))),"") | CK20: =IF(ISNUMBER(CI20),IF(CI20<$B$13,CI20,""),"") | CM20: =IF(CH20="","",IFERROR(IF(IF(AND(LEN(CH20)=9,ISERROR(FIND("-",LEFT(CH20,8))),ISNUMBER(-LEFT(CH20,8))),VALUE(LEFT(CH20,4)),VALUE(LEFT(CH20,FIND("-",CH20)-1)))<100,IF(AND(LEN(CH20)=9,ISERROR(FIND("-",LEFT(CH20,8))),ISNUMBER(-LEFT(CH20,8))),VALUE(LEFT(CH20,4)),VALUE(LEFT(CH20,FIND("-",CH20)-1)))+2000,IF(AND(LEN(CH20)=9,ISERROR(FIND("-",LEFT(CH20,8))),ISNUMBER(-LEFT(CH20,8))),VALUE(LEFT(CH20,4)),VALUE(LEFT(CH20,FIND("-",CH20)-1)))),"")) | CN20: =IF(CH20="","",IFERROR(IF(AND(LEN(CH20)=9,ISERROR(FIND("-",LEFT(CH20,8))),ISNUMBER(-LEFT(CH20,8))),VALUE(MID(CH20,5,2)),VALUE(MID(CH20,FIND("-",CH20)+1,FIND("-",CH20,FIND("-",CH20)+1)-FIND("-",CH20)-1))),"")) | CO20: =IF(CH20="","",IFERROR(IF(AND(LEN(CH20)=9,ISERROR(FIND("-",LEFT(CH20,8))),ISNUMBER(-LEFT(CH20,8))),VALUE(MID(CH20,7,2)),VALUE(MID(CH20,FIND("-",CH20,FIND("-",CH20)+1)+1,FIND("-",CH20,FIND("-",CH20,FIND("-",CH20)+1)+1)-FIND("-",CH20,FIND("-",CH20)+1)-1))),""))
A21: 웹과 같은 해 단위 나이 | B21: =IF(B37=999,"",B37) | CB21: 20 | CC21: =IF($B$1+CB21>90,0,12*MAX(0,$B$6-IF($B$1+CB21>=$B$23,$B$22,0))*(1+$B$4)^CB21/(1+$B$3)^(CB21-1)) | CE21: =IF($B$1+19>90,NA(),$B$1+19) | CF21: =IF(OR($B$21="",$B$1+19>90),NA(),INDEX($C$40:$BU$90,$B$21-$B$1+1,20)) | CH21: =IF(ISTEXT('월 가계부'!A21),SUBSTITUTE(SUBSTITUTE(SUBSTITUTE(SUBSTITUTE(SUBSTITUTE(SUBSTITUTE(SUBSTITUTE(SUBSTITUTE(SUBSTITUTE(TRIM('월 가계부'!A21),"년","-"),"월","-"),"일",""),".","-"),"/","-")," ","-"),"--","-"),"--","-"),"--","-")&"-","") | CI21: =IFERROR(IF('월 가계부'!A21="","",IF(ISNUMBER('월 가계부'!A21),IF(AND('월 가계부'!A21>=19000101,'월 가계부'!A21<=21001231),IF(AND(MOD(INT('월 가계부'!A21/100),100)>=1,MOD(INT('월 가계부'!A21/100),100)<=12,MOD(INT('월 가계부'!A21),100)>=1,MOD(INT('월 가계부'!A21),100)<=31),IF(MONTH(DATE(INT('월 가계부'!A21/10000),MOD(INT('월 가계부'!A21/100),100),MOD(INT('월 가계부'!A21),100)))=MOD(INT('월 가계부'!A21/100),100),DATE(INT('월 가계부'!A21/10000),MOD(INT('월 가계부'!A21/100),100),MOD(INT('월 가계부'!A21),100)),""),""),IF(AND('월 가계부'!A21>=36526,'월 가계부'!A21<73051),INT('월 가계부'!A21),"")),IF(OR(CM21="",CN21="",CO21=""),"",IF(AND(CM21>=2000,CM21<=2099,CN21>=1,CN21<=12,CO21>=1,CO21<=31),IF(MONTH(DATE(CM21,CN21,CO21))=CN21,DATE(CM21,CN21,CO21),""),"")))),"") | CJ21: =IFERROR(IF('월 가계부'!C21="","",IF(ISNUMBER('월 가계부'!C21),'월 가계부'!C21,VALUE(SUBSTITUTE(SUBSTITUTE(SUBSTITUTE(SUBSTITUTE(TRIM('월 가계부'!C21),",",""),"원","")," ",""),"−","-")))),"") | CK21: =IF(ISNUMBER(CI21),IF(CI21<$B$13,CI21,""),"") | CM21: =IF(CH21="","",IFERROR(IF(IF(AND(LEN(CH21)=9,ISERROR(FIND("-",LEFT(CH21,8))),ISNUMBER(-LEFT(CH21,8))),VALUE(LEFT(CH21,4)),VALUE(LEFT(CH21,FIND("-",CH21)-1)))<100,IF(AND(LEN(CH21)=9,ISERROR(FIND("-",LEFT(CH21,8))),ISNUMBER(-LEFT(CH21,8))),VALUE(LEFT(CH21,4)),VALUE(LEFT(CH21,FIND("-",CH21)-1)))+2000,IF(AND(LEN(CH21)=9,ISERROR(FIND("-",LEFT(CH21,8))),ISNUMBER(-LEFT(CH21,8))),VALUE(LEFT(CH21,4)),VALUE(LEFT(CH21,FIND("-",CH21)-1)))),"")) | CN21: =IF(CH21="","",IFERROR(IF(AND(LEN(CH21)=9,ISERROR(FIND("-",LEFT(CH21,8))),ISNUMBER(-LEFT(CH21,8))),VALUE(MID(CH21,5,2)),VALUE(MID(CH21,FIND("-",CH21)+1,FIND("-",CH21,FIND("-",CH21)+1)-FIND("-",CH21)-1))),"")) | CO21: =IF(CH21="","",IFERROR(IF(AND(LEN(CH21)=9,ISERROR(FIND("-",LEFT(CH21,8))),ISNUMBER(-LEFT(CH21,8))),VALUE(MID(CH21,7,2)),VALUE(MID(CH21,FIND("-",CH21,FIND("-",CH21)+1)+1,FIND("-",CH21,FIND("-",CH21,FIND("-",CH21)+1)+1)-FIND("-",CH21,FIND("-",CH21)+1)-1))),""))
A22: 국민연금 월 | B22: =N('은퇴 나이'!D16) | CB22: 21 | CC22: =IF($B$1+CB22>90,0,12*MAX(0,$B$6-IF($B$1+CB22>=$B$23,$B$22,0))*(1+$B$4)^CB22/(1+$B$3)^(CB22-1)) | CE22: =IF($B$1+20>90,NA(),$B$1+20) | CF22: =IF(OR($B$21="",$B$1+20>90),NA(),INDEX($C$40:$BU$90,$B$21-$B$1+1,21)) | CH22: =IF(ISTEXT('월 가계부'!A22),SUBSTITUTE(SUBSTITUTE(SUBSTITUTE(SUBSTITUTE(SUBSTITUTE(SUBSTITUTE(SUBSTITUTE(SUBSTITUTE(SUBSTITUTE(TRIM('월 가계부'!A22),"년","-"),"월","-"),"일",""),".","-"),"/","-")," ","-"),"--","-"),"--","-"),"--","-")&"-","") | CI22: =IFERROR(IF('월 가계부'!A22="","",IF(ISNUMBER('월 가계부'!A22),IF(AND('월 가계부'!A22>=19000101,'월 가계부'!A22<=21001231),IF(AND(MOD(INT('월 가계부'!A22/100),100)>=1,MOD(INT('월 가계부'!A22/100),100)<=12,MOD(INT('월 가계부'!A22),100)>=1,MOD(INT('월 가계부'!A22),100)<=31),IF(MONTH(DATE(INT('월 가계부'!A22/10000),MOD(INT('월 가계부'!A22/100),100),MOD(INT('월 가계부'!A22),100)))=MOD(INT('월 가계부'!A22/100),100),DATE(INT('월 가계부'!A22/10000),MOD(INT('월 가계부'!A22/100),100),MOD(INT('월 가계부'!A22),100)),""),""),IF(AND('월 가계부'!A22>=36526,'월 가계부'!A22<73051),INT('월 가계부'!A22),"")),IF(OR(CM22="",CN22="",CO22=""),"",IF(AND(CM22>=2000,CM22<=2099,CN22>=1,CN22<=12,CO22>=1,CO22<=31),IF(MONTH(DATE(CM22,CN22,CO22))=CN22,DATE(CM22,CN22,CO22),""),"")))),"") | CJ22: =IFERROR(IF('월 가계부'!C22="","",IF(ISNUMBER('월 가계부'!C22),'월 가계부'!C22,VALUE(SUBSTITUTE(SUBSTITUTE(SUBSTITUTE(SUBSTITUTE(TRIM('월 가계부'!C22),",",""),"원","")," ",""),"−","-")))),"") | CK22: =IF(ISNUMBER(CI22),IF(CI22<$B$13,CI22,""),"") | CM22: =IF(CH22="","",IFERROR(IF(IF(AND(LEN(CH22)=9,ISERROR(FIND("-",LEFT(CH22,8))),ISNUMBER(-LEFT(CH22,8))),VALUE(LEFT(CH22,4)),VALUE(LEFT(CH22,FIND("-",CH22)-1)))<100,IF(AND(LEN(CH22)=9,ISERROR(FIND("-",LEFT(CH22,8))),ISNUMBER(-LEFT(CH22,8))),VALUE(LEFT(CH22,4)),VALUE(LEFT(CH22,FIND("-",CH22)-1)))+2000,IF(AND(LEN(CH22)=9,ISERROR(FIND("-",LEFT(CH22,8))),ISNUMBER(-LEFT(CH22,8))),VALUE(LEFT(CH22,4)),VALUE(LEFT(CH22,FIND("-",CH22)-1)))),"")) | CN22: =IF(CH22="","",IFERROR(IF(AND(LEN(CH22)=9,ISERROR(FIND("-",LEFT(CH22,8))),ISNUMBER(-LEFT(CH22,8))),VALUE(MID(CH22,5,2)),VALUE(MID(CH22,FIND("-",CH22)+1,FIND("-",CH22,FIND("-",CH22)+1)-FIND("-",CH22)-1))),"")) | CO22: =IF(CH22="","",IFERROR(IF(AND(LEN(CH22)=9,ISERROR(FIND("-",LEFT(CH22,8))),ISNUMBER(-LEFT(CH22,8))),VALUE(MID(CH22,7,2)),VALUE(MID(CH22,FIND("-",CH22,FIND("-",CH22)+1)+1,FIND("-",CH22,FIND("-",CH22,FIND("-",CH22)+1)+1)-FIND("-",CH22,FIND("-",CH22)+1)-1))),""))
A23: 연금 개시 나이 | B23: =IF(YEAR(TODAY())-B1<=1952,60,IF(YEAR(TODAY())-B1<=1956,61,IF(YEAR(TODAY())-B1<=1960,62,IF(YEAR(TODAY())-B1<=1964,63,IF(YEAR(TODAY())-B1<=1968,64,65))))) | CB23: 22 | CC23: =IF($B$1+CB23>90,0,12*MAX(0,$B$6-IF($B$1+CB23>=$B$23,$B$22,0))*(1+$B$4)^CB23/(1+$B$3)^(CB23-1)) | CE23: =IF($B$1+21>90,NA(),$B$1+21) | CF23: =IF(OR($B$21="",$B$1+21>90),NA(),INDEX($C$40:$BU$90,$B$21-$B$1+1,22)) | CH23: =IF(ISTEXT('월 가계부'!A23),SUBSTITUTE(SUBSTITUTE(SUBSTITUTE(SUBSTITUTE(SUBSTITUTE(SUBSTITUTE(SUBSTITUTE(SUBSTITUTE(SUBSTITUTE(TRIM('월 가계부'!A23),"년","-"),"월","-"),"일",""),".","-"),"/","-")," ","-"),"--","-"),"--","-"),"--","-")&"-","") | CI23: =IFERROR(IF('월 가계부'!A23="","",IF(ISNUMBER('월 가계부'!A23),IF(AND('월 가계부'!A23>=19000101,'월 가계부'!A23<=21001231),IF(AND(MOD(INT('월 가계부'!A23/100),100)>=1,MOD(INT('월 가계부'!A23/100),100)<=12,MOD(INT('월 가계부'!A23),100)>=1,MOD(INT('월 가계부'!A23),100)<=31),IF(MONTH(DATE(INT('월 가계부'!A23/10000),MOD(INT('월 가계부'!A23/100),100),MOD(INT('월 가계부'!A23),100)))=MOD(INT('월 가계부'!A23/100),100),DATE(INT('월 가계부'!A23/10000),MOD(INT('월 가계부'!A23/100),100),MOD(INT('월 가계부'!A23),100)),""),""),IF(AND('월 가계부'!A23>=36526,'월 가계부'!A23<73051),INT('월 가계부'!A23),"")),IF(OR(CM23="",CN23="",CO23=""),"",IF(AND(CM23>=2000,CM23<=2099,CN23>=1,CN23<=12,CO23>=1,CO23<=31),IF(MONTH(DATE(CM23,CN23,CO23))=CN23,DATE(CM23,CN23,CO23),""),"")))),"") | CJ23: =IFERROR(IF('월 가계부'!C23="","",IF(ISNUMBER('월 가계부'!C23),'월 가계부'!C23,VALUE(SUBSTITUTE(SUBSTITUTE(SUBSTITUTE(SUBSTITUTE(TRIM('월 가계부'!C23),",",""),"원","")," ",""),"−","-")))),"") | CK23: =IF(ISNUMBER(CI23),IF(CI23<$B$13,CI23,""),"") | CM23: =IF(CH23="","",IFERROR(IF(IF(AND(LEN(CH23)=9,ISERROR(FIND("-",LEFT(CH23,8))),ISNUMBER(-LEFT(CH23,8))),VALUE(LEFT(CH23,4)),VALUE(LEFT(CH23,FIND("-",CH23)-1)))<100,IF(AND(LEN(CH23)=9,ISERROR(FIND("-",LEFT(CH23,8))),ISNUMBER(-LEFT(CH23,8))),VALUE(LEFT(CH23,4)),VALUE(LEFT(CH23,FIND("-",CH23)-1)))+2000,IF(AND(LEN(CH23)=9,ISERROR(FIND("-",LEFT(CH23,8))),ISNUMBER(-LEFT(CH23,8))),VALUE(LEFT(CH23,4)),VALUE(LEFT(CH23,FIND("-",CH23)-1)))),"")) | CN23: =IF(CH23="","",IFERROR(IF(AND(LEN(CH23)=9,ISERROR(FIND("-",LEFT(CH23,8))),ISNUMBER(-LEFT(CH23,8))),VALUE(MID(CH23,5,2)),VALUE(MID(CH23,FIND("-",CH23)+1,FIND("-",CH23,FIND("-",CH23)+1)-FIND("-",CH23)-1))),"")) | CO23: =IF(CH23="","",IFERROR(IF(AND(LEN(CH23)=9,ISERROR(FIND("-",LEFT(CH23,8))),ISNUMBER(-LEFT(CH23,8))),VALUE(MID(CH23,7,2)),VALUE(MID(CH23,FIND("-",CH23,FIND("-",CH23)+1)+1,FIND("-",CH23,FIND("-",CH23,FIND("-",CH23)+1)+1)-FIND("-",CH23,FIND("-",CH23)+1)-1))),""))
