Workbook

Sheet 내 연봉 넣기
A1: 내 연봉은 상위 몇 % 근처일까
A2: 국세청 2024년 귀속 근로소득 자료(연말정산한 근로자 2,108만명)로 봅니다.
A4: ① 1년 총급여(만원) | C4: 5000 | D4: ← 노란 칸에 숫자만 넣으세요. 원천징수영수증의 「총급여」(비과세 뺀 세전 금액)
A6: ② 바로 아래 구간 | C6: =IF(C4<MIN(원자료!$D$4:$D$112),"맨 아래 구간 평균보다 적음",INDEX(원자료!$A$4:$A$112,MATCH(C4,원자료!$D$4:$D$112,1)))
A7: 그 구간 평균(만원) | C7: =IF(C4<MIN(원자료!$D$4:$D$112),"",INDEX(원자료!$D$4:$D$112,MATCH(C4,원자료!$D$4:$D$112,1)))
A8: ③ 바로 위 구간 | C8: =IF(C4<MIN(원자료!$D$4:$D$112),INDEX(원자료!$A$4:$A$112,1),IF(C4>=MAX(원자료!$D$4:$D$112),"위 구간 없음(상위 0.1% 평균 이상)",INDEX(원자료!$A$4:$A$112,MATCH(C4,원자료!$D$4:$D$112,1)+1)))
A9: 그 구간 평균(만원) | C9: =IF(C4<MIN(원자료!$D$4:$D$112),INDEX(원자료!$D$4:$D$112,1),IF(C4>=MAX(원자료!$D$4:$D$112),"",INDEX(원자료!$D$4:$D$112,MATCH(C4,원자료!$D$4:$D$112,1)+1)))
A11: 한 줄로
A12: =IF(C4>=MAX(원자료!$D$4:$D$112),"총급여 "&TEXT(C4,"#,##0")&"만원은 상위 0.1% 구간 평균("&TEXT(MAX(원자료!$D$4:$D$112),"#,##0")&"만원)과 같거나 많아요.",IF(C4<MIN(원자료!$D$4:$D$112),"총급여 "&TEXT(C4,"#,##0")&"만원은 맨 아래 구간 평균("&TEXT(MIN(원자료!$D$4:$D$112),"#,##0")&"만원)보다 적어요.","총급여 "&TEXT(C4,"#,##0")&"만원은 「"&C6&"」 구간 평균("&TEXT(C7,"#,##0")&"만원)과 「"&C8&"」 구간 평균("&TEXT(C9,"#,##0")&"만원) 사이예요."))
A14: 읽는 법
A15: · 국세청 자료는 구간마다 「합계」만 있어요. 그래서 정확한 경계값(상위 10%가 몇 만원부터인지)은 못 짚고, 두 구간 평균 사이로만 말합니다.
A16: · 예) 「상위 10%」 구간 = 위에서 9%와 10% 사이에 있는 약 21만명입니다. 「상위 10%」 구간 평균보다 많으면 위에서 10% 안쪽일 가능성이 큽니다.
A17: · 연말정산 자료라 중간에 입사·퇴사한 사람도 들어 있어요. 맨 아래 1% 구간 평균은 21만원입니다.
A18: · 총급여는 비과세(식대 등)를 뺀 세전 금액입니다. 사업·임대·금융 소득은 들어 있지 않아요.
A19: · 2024년 한 해(2025년 연말정산) 자료입니다. 다음 해 자료가 나오면 원자료 시트만 바꾸면 됩니다.
A20: · 투자·이직 권유가 아닙니다. 공개 통계로 내 위치를 보는 표입니다.
A22: 출처: 국세청 근로소득 백분위(천분위) 자료, 공공데이터포털 https://www.data.go.kr/data/15082063/fileData.do
A23: 만든 곳: 파이어맵 카페(cafe.naver.com/firemap) · 검산 기록은 카페 글에 있습니다.

Sheet 주요 구간
A1: 주요 구간 평균 총급여(만원)
A3: 구간 | B3: 구간 평균(만원) | C3: 뜻
A4: 상위 0.1% | B4: =원자료!D112 | C4: 위에서 0.1% 언저리 사람들의 평균
A5: 상위 1.0% | B5: =원자료!D103 | C5: 위에서 1.0% 언저리 사람들의 평균
A6: 상위 5% | B6: =원자료!D99 | C6: 위에서 5% 언저리 사람들의 평균
A7: 상위 10% | B7: =원자료!D94 | C7: 위에서 10% 언저리 사람들의 평균
A8: 상위 20% | B8: =원자료!D84 | C8: 위에서 20% 언저리 사람들의 평균
A9: 상위 30% | B9: =원자료!D74 | C9: 위에서 30% 언저리 사람들의 평균
A10: 상위 50% | B10: =원자료!D54 | C10: 위에서 50% 언저리 사람들의 평균
A11: 상위 51% | B11: =원자료!D53 | C11: 위에서 51% 언저리 사람들의 평균
A12: 상위 70% | B12: =원자료!D34 | C12: 위에서 70% 언저리 사람들의 평균
A13: 상위 90% | B13: =원자료!D14 | C13: 위에서 90% 언저리 사람들의 평균
A15: 「상위 50%」·「상위 51%」 두 구간 평균 사이가 한가운데(중간) 근처입니다.

Sheet 원자료
A1: 국세청 근로소득 백분위(천분위) 자료 · 2024년 귀속(2025년 연말정산) · 공공데이터포털 15082063(수정 2026-05-08)
A2: https://www.data.go.kr/data/15082063/fileData.do
A3: 구간 | B3: 인원(명) | C3: 총급여 합계(억원) | D3: 구간 평균 총급여(만원) | E3: 이 구간보다 위에 있는 사람 비율
A4: 상위 100% | B4: 210786 | C4: 450 | D4: =ROUND(C4*10000/B4,0) | E4: =SUM(B5:B113)/SUM($B$4:$B$112)
A5: 상위 99% | B5: 210785 | C5: 1932 | D5: =ROUND(C5*10000/B5,0) | E5: =SUM(B6:B113)/SUM($B$4:$B$112)
A6: 상위 98% | B6: 210786 | C6: 3480 | D6: =ROUND(C6*10000/B6,0) | E6: =SUM(B7:B113)/SUM($B$4:$B$112)
A7: 상위 97% | B7: 210785 | C7: 4876 | D7: =ROUND(C7*10000/B7,0) | E7: =SUM(B8:B113)/SUM($B$4:$B$112)
A8: 상위 96% | B8: 210785 | C8: 6429 | D8: =ROUND(C8*10000/B8,0) | E8: =SUM(B9:B113)/SUM($B$4:$B$112)
A9: 상위 95% | B9: 210786 | C9: 8088 | D9: =ROUND(C9*10000/B9,0) | E9: =SUM(B10:B113)/SUM($B$4:$B$112)
A10: 상위 94% | B10: 210785 | C10: 9613 | D10: =ROUND(C10*10000/B10,0) | E10: =SUM(B11:B113)/SUM($B$4:$B$112)
A11: 상위 93% | B11: 210785 | C11: 11291 | D11: =ROUND(C11*10000/B11,0) | E11: =SUM(B12:B113)/SUM($B$4:$B$112)
A12: 상위 92% | B12: 210786 | C12: 12983 | D12: =ROUND(C12*10000/B12,0) | E12: =SUM(B13:B113)/SUM($B$4:$B$112)
A13: 상위 91% | B13: 210785 | C13: 14618 | D13: =ROUND(C13*10000/B13,0) | E13: =SUM(B14:B113)/SUM($B$4:$B$112)
A14: 상위 90% | B14: 210785 | C14: 16165 | D14: =ROUND(C14*10000/B14,0) | E14: =SUM(B15:B113)/SUM($B$4:$B$112)
A15: 상위 89% | B15: 210786 | C15: 17446 | D15: =ROUND(C15*10000/B15,0) | E15: =SUM(B16:B113)/SUM($B$4:$B$112)
A16: 상위 88% | B16: 210785 | C16: 19255 | D16: =ROUND(C16*10000/B16,0) | E16: =SUM(B17:B113)/SUM($B$4:$B$112)
A17: 상위 87% | B17: 210785 | C17: 20942 | D17: =ROUND(C17*10000/B17,0) | E17: =SUM(B18:B113)/SUM($B$4:$B$112)
A18: 상위 86% | B18: 210786 | C18: 22734 | D18: =ROUND(C18*10000/B18,0) | E18: =SUM(B19:B113)/SUM($B$4:$B$112)
A19: 상위 85% | B19: 210785 | C19: 24654 | D19: =ROUND(C19*10000/B19,0) | E19: =SUM(B20:B113)/SUM($B$4:$B$112)
A20: 상위 84% | B20: 210785 | C20: 26056 | D20: =ROUND(C20*10000/B20,0) | E20: =SUM(B21:B113)/SUM($B$4:$B$112)
A21: 상위 83% | B21: 210786 | C21: 27814 | D21: =ROUND(C21*10000/B21,0) | E21: =SUM(B22:B113)/SUM($B$4:$B$112)
A22: 상위 82% | B22: 210785 | C22: 29762 | D22: =ROUND(C22*10000/B22,0) | E22: =SUM(B23:B113)/SUM($B$4:$B$112)
A23: 상위 81% | B23: 210785 | C23: 31593 | D23: =ROUND(C23*10000/B23,0) | E23: =SUM(B24:B113)/SUM($B$4:$B$112)
A24: 상위 80% | B24: 210786 | C24: 33380 | D24: =ROUND(C24*10000/B24,0) | E24: =SUM(B25:B113)/SUM($B$4:$B$112)
A25: 상위 79% | B25: 210785 | C25: 35230 | D25: =ROUND(C25*10000/B25,0) | E25: =SUM(B26:B113)/SUM($B$4:$B$112)
A26: 상위 78% | B26: 210786 | C26: 37171 | D26: =ROUND(C26*10000/B26,0) | E26: =SUM(B27:B113)/SUM($B$4:$B$112)
A27: 상위 77% | B27: 210785 | C27: 38743 | D27: =ROUND(C27*10000/B27,0) | E27: =SUM(B28:B113)/SUM($B$4:$B$112)
A28: 상위 76% | B28: 210785 | C28: 40523 | D28: =ROUND(C28*10000/B28,0) | E28: =SUM(B29:B113)/SUM($B$4:$B$112)
A29: 상위 75% | B29: 210786 | C29: 42336 | D29: =ROUND(C29*10000/B29,0) | E29: =SUM(B30:B113)/SUM($B$4:$B$112)
A30: 상위 74% | B30: 210785 | C30: 44044 | D30: =ROUND(C30*10000/B30,0) | E30: =SUM(B31:B113)/SUM($B$4:$B$112)
A31: 상위 73% | B31: 210785 | C31: 45689 | D31: =ROUND(C31*10000/B31,0) | E31: =SUM(B32:B113)/SUM($B$4:$B$112)
A32: 상위 72% | B32: 210786 | C32: 47284 | D32: =ROUND(C32*10000/B32,0) | E32: =SUM(B33:B113)/SUM($B$4:$B$112)
A33: 상위 71% | B33: 210785 | C33: 48716 | D33: =ROUND(C33*10000/B33,0) | E33: =SUM(B34:B113)/SUM($B$4:$B$112)
A34: 상위 70% | B34: 210785 | C34: 50259 | D34: =ROUND(C34*10000/B34,0) | E34: =SUM(B35:B113)/SUM($B$4:$B$112)
A35: 상위 69% | B35: 210786 | C35: 51212 | D35: =ROUND(C35*10000/B35,0) | E35: =SUM(B36:B113)/SUM($B$4:$B$112)
A36: 상위 68% | B36: 210785 | C36: 52159 | D36: =ROUND(C36*10000/B36,0) | E36: =SUM(B37:B113)/SUM($B$4:$B$112)
A37: 상위 67% | B37: 210785 | C37: 52864 | D37: =ROUND(C37*10000/B37,0) | E37: =SUM(B38:B113)/SUM($B$4:$B$112)
A38: 상위 66% | B38: 210786 | C38: 53596 | D38: =ROUND(C38*10000/B38,0) | E38: =SUM(B39:B113)/SUM($B$4:$B$112)
A39: 상위 65% | B39: 210785 | C39: 54740 | D39: =ROUND(C39*10000/B39,0) | E39: =SUM(B40:B113)/SUM($B$4:$B$112)
A40: 상위 64% | B40: 210785 | C40: 55752 | D40: =ROUND(C40*10000/B40,0) | E40: =SUM(B41:B113)/SUM($B$4:$B$112)
...
